Workbook

Sheet Loads
A1: name | B1: P | C1: Q | K1: Wyjściowe | Q1: Poczatkowe | U1: Matlab
A2: Ld1 | B2: =_xlfn.XLOOKUP(A2,'Do podmianki'!A:A,'Do podmianki'!B:B,K2) -> 6.7 | C2: =_xlfn.XLOOKUP(A2,'Do podmianki'!B:B,'Do podmianki'!C:C,L2) -> 1.1 | K2: 6.7 | L2: 1.1 | Q2: 6.7 | R2: 1.1 | U2: 12.285377 | V2: 1.1
A3: Ld10 | B3: =_xlfn.XLOOKUP(A3,'Do podmianki'!A:A,'Do podmianki'!B:B,K3) -> 7.5 | C3: =_xlfn.XLOOKUP(A3,'Do podmianki'!B:B,'Do podmianki'!C:C,L3) -> 1.7 | K3: 7.5 | L3: 1.7 | Q3: 7.5 | R3: 1.7 | U3: 20.20262 | V3: 1.7
A4: Ld100 | B4: =_xlfn.XLOOKUP(A4,'Do podmianki'!A:A,'Do podmianki'!B:B,K4) -> 12.4 | C4: =_xlfn.XLOOKUP(A4,'Do podmianki'!B:B,'Do podmianki'!C:C,L4) -> 0.9 | K4: 12.4 | L4: 0.9 | Q4: 12.4 | R4: 0.9 | U4: 10.620026 | V4: 0.9
A5: Ld102 | B5: =_xlfn.XLOOKUP(A5,'Do podmianki'!A:A,'Do podmianki'!B:B,K5) -> 6.3 | C5: =_xlfn.XLOOKUP(A5,'Do podmianki'!B:B,'Do podmianki'!C:C,L5) -> 0.4 | K5: 6.3 | L5: 0.4 | Q5: 6.3 | R5: 0.4 | U5: 4.368134 | V5: 0.4
A6: Ld103 | B6: =_xlfn.XLOOKUP(A6,'Do podmianki'!A:A,'Do podmianki'!B:B,K6) -> 4.8 | C6: =_xlfn.XLOOKUP(A6,'Do podmianki'!B:B,'Do podmianki'!C:C,L6) -> 0.1 | K6: 4.8 | L6: 0.1 | Q6: 4.8 | R6: 0.1 | U6: 1.365042 | V6: 0.1
A7: Ld104 | B7: =_xlfn.XLOOKUP(A7,'Do podmianki'!A:A,'Do podmianki'!B:B,K7) -> 8.3 | C7: =_xlfn.XLOOKUP(A7,'Do podmianki'!B:B,'Do podmianki'!C:C,L7) -> 0.6 | K7: 8.3 | L7: 0.6 | Q7: 8.3 | R7: 0.6 | U7: 6.770607 | V7: 0.6
A8: Ld105 | B8: =_xlfn.XLOOKUP(A8,'Do podmianki'!A:A,'Do podmianki'!B:B,K8) -> 4.2 | C8: =_xlfn.XLOOKUP(A8,'Do podmianki'!B:B,'Do podmianki'!C:C,L8) -> 0.1 | K8: 4.2 | L8: 0.1 | Q8: 4.2 | R8: 0.1 | U8: 0.627919 | V8: 0.1
A9: Ld107 | B9: =_xlfn.XLOOKUP(A9,'Do podmianki'!A:A,'Do podmianki'!B:B,K9) -> 11.6 | C9: =_xlfn.XLOOKUP(A9,'Do podmianki'!B:B,'Do podmianki'!C:C,L9) -> 1.6 | K9: 11.6 | L9: 1.6 | Q9: 11.6 | R9: 1.6 | U9: 18.673773 | V9: 1.6
A10: Ld108 | B10: =_xlfn.XLOOKUP(A10,'Do podmianki'!A:A,'Do podmianki'!B:B,K10) -> 8.2 | C10: =_xlfn.XLOOKUP(A10,'Do podmianki'!B:B,'Do podmianki'!C:C,L10) -> 0.4 | K10: 8.2 | L10: 0.4 | Q10: 8.2 | R10: 0.4 | U10: 4.190679 | V10: 0.4
A11: Ld109 | B11: =_xlfn.XLOOKUP(A11,'Do podmianki'!A:A,'Do podmianki'!B:B,K11) -> 10 | C11: =_xlfn.XLOOKUP(A11,'Do podmianki'!B:B,'Do podmianki'!C:C,L11) -> 1 | K11: 10 | L11: 1 | Q11: 10 | R11: 1 | U11: 11.329847 | V11: 1
A12: Ld11 | B12: =_xlfn.XLOOKUP(A12,'Do podmianki'!A:A,'Do podmianki'!B:B,K12) -> 8.3 | C12: =_xlfn.XLOOKUP(A12,'Do podmianki'!B:B,'Do podmianki'!C:C,L12) -> 0.7 | K12: 8.3 | L12: 0.7 | Q12: 8.3 | R12: 0.7 | U12: 8.599764 | V12: 0.7
A13: Ld110 | B13: =_xlfn.XLOOKUP(A13,'Do podmianki'!A:A,'Do podmianki'!B:B,K13) -> 6 | C13: =_xlfn.XLOOKUP(A13,'Do podmianki'!B:B,'Do podmianki'!C:C,L13) -> 0.2 | K13: 6 | L13: 0.2 | Q13: 6 | R13: 0.2 | U13: 2.675482 | V13: 0.2
... A19: Ld120 | B19: =_xlfn.XLOOKUP(A19,'Do podmianki'!A:A,'Do podmianki'!B:B,K19) -> 90 | C19: =_xlfn.XLOOKUP(A19,'Do podmianki'!B:B,'Do podmianki'!C:C,L19) -> 6.3 | K19: 90 | L19: 6.3 | Q19: 90 | R19: 6.3 | U19: 73.029739 | V19: 6.3
A20: Ld121 | B20: 12 | C20: =_xlfn.XLOOKUP(A20,'Do podmianki'!B:B,'Do podmianki'!C:C,L20) -> 0.9 | K20: 26.2 | L20: 0.9 | Q20: 26.200001 | R20: 0.9 | U20: 10.647326 | V20: 0.9
A21: Ld123 | B21: =_xlfn.XLOOKUP(A21,'Do podmianki'!A:A,'Do podmianki'!B:B,K21) -> 32 | C21: =_xlfn.XLOOKUP(A21,'Do podmianki'!B:B,'Do podmianki'!C:C,L21) -> 3.2 | K21: 32 | L21: 3.2 | Q21: 32 | R21: 3.2 | U21: 37.729755 | V21: 3.2
A22: Ld124 | B22: =_xlfn.XLOOKUP(A22,'Do podmianki'!A:A,'Do podmianki'!B:B,K22) -> 8 | C22: =_xlfn.XLOOKUP(A22,'Do podmianki'!B:B,'Do podmianki'!C:C,L22) -> 0.7 | K22: 8 | L22: 0.7 | Q22: 8 | R22: 0.7 | U22: 7.903592 | V22: 0.7
A23: Ld126 | B23: =_xlfn.XLOOKUP(A23,'Do podmianki'!A:A,'Do podmianki'!B:B,K23) -> 113 | C23: =_xlfn.XLOOKUP(A23,'Do podmianki'!B:B,'Do podmianki'!C:C,L23) -> 4.5 | K23: 113 | L23: 4.5 | Q23: 113 | R23: 4.5 | U23: 51.980793 | V23: 4.5
A24: Ld127 | B24: =_xlfn.XLOOKUP(A24,'Do podmianki'!A:A,'Do podmianki'!B:B,K24) -> 7.5 | C24: =_xlfn.XLOOKUP(A24,'Do podmianki'!B:B,'Do podmianki'!C:C,L24) -> 0.7 | K24: 7.5 | L24: 0.7 | Q24: 7.5 | R24: 0.7 | U24: 7.917243 | V24: 0.7
A25: Ld13 | B25: =_xlfn.XLOOKUP(A25,'Do podmianki'!A:A,'Do podmianki'!B:B,K25) -> 9.7 | C25: =_xlfn.XLOOKUP(A25,'Do podmianki'!B:B,'Do podmianki'!C:C,L25) -> 2 | K25: 9.7 | L25: 2 | Q25: 9.7 | R25: 2 | U25: 23.096508 | V25: 2
A26: Ld135 | B26: =_xlfn.XLOOKUP(A26,'Do podmianki'!A:A,'Do podmianki'!B:B,K26) -> 14 | C26: =_xlfn.XLOOKUP(A26,'Do podmianki'!B:B,'Do podmianki'!C:C,L26) -> 0.6 | K26: 14 | L26: 0.6 | Q26: 14 | R26: 0.6 | U26: 7.535031 | V26: 0.6
A27: Ld136 | B27: =_xlfn.XLOOKUP(A27,'Do podmianki'!A:A,'Do podmianki'!B:B,K27) -> 88.2 | C27: =_xlfn.XLOOKUP(A27,'Do podmianki'!B:B,'Do podmianki'!C:C,L27) -> 3.2 | K27: 88.2 | L27: 3.2 | Q27: 88.199997 | R27: 3.2 | U27: 37.347546 | V27: 3.2
A28: Ld137 | B28: =_xlfn.XLOOKUP(A28,'Do podmianki'!A:A,'Do podmianki'!B:B,K28) -> 125 | C28: =_xlfn.XLOOKUP(A28,'Do podmianki'!B:B,'Do podmianki'!C:C,L28) -> 9.7 | K28: 125 | L28: 9.7 | Q28: 225 | R28: 9.7 | U28: 112.84801 | V28: 9.7
A29: Ld138 | B29: =_xlfn.XLOOKUP(A29,'Do podmianki'!A:A,'Do podmianki'!B:B,K29) -> 26.5 | C29: =_xlfn.XLOOKUP(A29,'Do podmianki'!B:B,'Do podmianki'!C:C,L29) -> 7 | K29: 26.5 | L29: 7 | Q29: 26.5 | R29: 7 | U29: 81.219986 | V29: 7
A30: Ld139 | B30: =_xlfn.XLOOKUP(A30,'Do podmianki'!A:A,'Do podmianki'!B:B,K30) -> 33 | C30: =_xlfn.XLOOKUP(A30,'Do podmianki'!B:B,'Do podmianki'!C:C,L30) -> 1.9 | K30: 33 | L30: 1.9 | Q30: 33 | R30: 1.9 | U30: 11.84067 | V30: 1.9
A31: Ld14 | B31: =_xlfn.XLOOKUP(A31,'Do podmianki'!A:A,'Do podmianki'!B:B,K31) -> 46.250901 | C31: =_xlfn.XLOOKUP(A31,'Do podmianki'!B:B,'Do podmianki'!C:C,L31) -> 4.5 | K31: 51.6 | L31: 4.5 | Q31: 51.599998 | R31: 4.5 | U31: 52.922672 | V31: 4.5
A32: Ld140 | B32: =_xlfn.XLOOKUP(A32,'Do podmianki'!A:A,'Do podmianki'!B:B,K32) -> 38.7 | C32: =_xlfn.XLOOKUP(A32,'Do podmianki'!B:B,'Do podmianki'!C:C,L32) -> 1.7 | K32: 38.7 | L32: 1.7 | Q32: 38.700001 | R32: 1.7 | U32: 19.793106 | V32: 1.7
... A167: Ld72 | B167: =_xlfn.XLOOKUP(A167,'Do podmianki'!A:A,'Do podmianki'!B:B,K167) -> 4.7 | C167: =_xlfn.XLOOKUP(A167,'Do podmianki'!B:B,'Do podmianki'!C:C,L167) -> 0.1 | K167: 4.7 | L167: 0.1 | Q167: 4.7 | R167: 0.1 | U167: 1.365042 | V167: 0.1
A168: Ld73 | B168: 30 | C168: =_xlfn.XLOOKUP(A168,'Do podmianki'!B:B,'Do podmianki'!C:C,L168) -> 0.6 | K168: 1 | L168: 0.6 | Q168: 1 | R168: 0.6 | U168: 6.770607 | V168: 0.6
A169: Ld74 | B169: =_xlfn.XLOOKUP(A169,'Do podmianki'!A:A,'Do podmianki'!B:B,K169) -> 4.4 | C169: =_xlfn.XLOOKUP(A169,'Do podmianki'!B:B,'Do podmianki'!C:C,L169) -> 0.3 | K169: 4.4 | L169: 0.3 | Q169: 4.4 | R169: 0.3 | U169: 0.627919 | V169: 0.3
A170: Ld76 | B170: =_xlfn.XLOOKUP(A170,'Do podmianki'!A:A,'Do podmianki'!B:B,K170) -> 16.3 | C170: =_xlfn.XLOOKUP(A170,'Do podmianki'!B:B,'Do podmianki'!C:C,L170) -> 0.1 | K170: 16.3 | L170: 0.1 | Q170: 16.299999 | R170: 0.1 | U170: 18.673773 | V170: 0.1
A171: Ld77 | B171: =_xlfn.XLOOKUP(A171,'Do podmianki'!A:A,'Do podmianki'!B:B,K171) -> 6.1 | C171: =_xlfn.XLOOKUP(A171,'Do podmianki'!B:B,'Do podmianki'!C:C,L171) -> 1.6 | K171: 6.1 | L171: 1.6 | Q171: 6.1 | R171: 1.6 | U171: 4.190679 | V171: 1.6
A172: Ld771 | B172: =_xlfn.XLOOKUP(A172,'Do podmianki'!A:A,'Do podmianki'!B:B,K172) -> 5.5 | C172: =_xlfn.XLOOKUP(A172,'Do podmianki'!B:B,'Do podmianki'!C:C,L172) -> 0.4 | K172: 5.5 | L172: 0.4 | Q172: 5.5 | R172: 0.4 | U172: 11.329847 | V172: 0.4
A173: Ld772 | B173: =_xlfn.XLOOKUP(A173,'Do podmianki'!A:A,'Do podmianki'!B:B,K173) -> 9.7 | C173: =_xlfn.XLOOKUP(A173,'Do podmianki'!B:B,'Do podmianki'!C:C,L173) -> 1 | K173: 9.7 | L173: 1 | Q173: 9.7 | R173: 1 | U173: 8.599764 | V173: 1
A174: Ld78 | B174: =_xlfn.XLOOKUP(A174,'Do podmianki'!A:A,'Do podmianki'!B:B,K174) -> 5.8 | C174: =_xlfn.XLOOKUP(A174,'Do podmianki'!B:B,'Do podmianki'!C:C,L174) -> 0.7 | K174: 5.8 | L174: 0.7 | Q174: 5.8 | R174: 0.7 | U174: 2.675482 | V174: 0.7
A175: Ld789 | B175: =_xlfn.XLOOKUP(A175,'Do podmianki'!A:A,'Do podmianki'!B:B,K175) -> 9 | C175: =_xlfn.XLOOKUP(A175,'Do podmianki'!B:B,'Do podmianki'!C:C,L175) -> 0.2 | K175: 9 | L175: 0.2 | Q175: 9 | R175: 0.2 | U175: 3.57641 | V175: 0.2
A176: Ld79 | B176: =_xlfn.XLOOKUP(A176,'Do podmianki'!A:A,'Do podmianki'!B:B,K176) -> 51.429258 | C176: =_xlfn.XLOOKUP(A176,'Do podmianki'!B:B,'Do podmianki'!C:C,L176) -> 0.3 | K176: 59.1 | L176: 0.3 | Q176: 6.1 | R176: 0.3 | U176: 2.484376 | V176: 0.3
A177: Ld8 | B177: =_xlfn.XLOOKUP(A177,'Do podmianki'!A:A,'Do podmianki'!B:B,K177) -> 5 | C177: =_xlfn.XLOOKUP(A177,'Do podmianki'!B:B,'Do podmianki'!C:C,L177) -> 0.2 | K177: 5 | L177: 0.2 | Q177: 5 | R177: 0.2 | U177: 1.924709 | V177: 0.2
A178: Ld80 | B178: =_xlfn.XLOOKUP(A178,'Do podmianki'!A:A,'Do podmianki'!B:B,K178) -> 4.8 | C178: =_xlfn.XLOOKUP(A178,'Do podmianki'!B:B,'Do podmianki'!C:C,L178) -> 0.2 | K178: 4.8 | L178: 0.2 | Q178: 4.8 | R178: 0.2 | U178: 2.675482 | V178: 0.2
A179: Ld81 | B179: =_xlfn.XLOOKUP(A179,'Do podmianki'!A:A,'Do podmianki'!B:B,K179) -> 6.8 | C179: =_xlfn.XLOOKUP(A179,'Do podmianki'!B:B,'Do podmianki'!C:C,L179) -> 0.2 | K179: 6.8 | L179: 0.2 | Q179: 6.8 | R179: 0.2 | U179: 3.57641 | V179: 0.2
...

Sheet Generators
A1: name | B1: P | C1: Q | K1: Wyjściowe | O1: MATLAB | U1: Początkowe | X1: 49.5 | Y1: 37.400002 | Z1: 61.5 | AA1: 38.799999 | AB1: 24.700001 | AC1: 106.9 | AD1: 29.5 | AE1: 84.699997 | AF1: 49.5 | AG1: 29.5 | AH1: 3.1 | AI1: 197.7 | AJ1: 291.39999 | AK1: 51.5 | AL1: 54.099998 | AM1: 14 | AN1: 30.1 | AO1: 18.700001 | AP1: 46.099998 | AQ1: 36.799999 | AR1: 56.799999 | AS1: 20.5 | AT1: 44.099998 | AU1: 103.6 | AV1: 49.5 | AW1: 30.700001 | AX1: 26.1 | AY1: 38.799999 | AZ1: 27.4 | BA1: 3.3 | BB1: 40.799999 | BC1: 32.099998 | BD1: 13.4 | BE1: 46.099998 | BF1: 6.7 | BG1: 14.7 | BH1: 65.5 | BI1: 9.4 | BJ1: 11.6 | BK1: 145.7 | BL1: 46.799999 | BM1: 37.400002 | BN1: 77.5 | BO1: 10.6 | BP1: 38.099998 | BQ1: 149.7 | BR1: 139 | BS1: 18.700001 | BT1: 26.700001 | BU1: 44.599998 | BV1: 55.799999 | BW1: 52 | BX1: 21.4 | BY1: 6.7 | BZ1: 236 | CA1: 40.299999 | CB1: 33.200001 | CC1: 80.199997 | CD1: 60.200001 | CE1: 38.799999 | CF1: 42.099998 | CG1: 64.199997 | CH1: 98.900002 | CI1: 38.799999 | CJ1: 1
A2: Gen1 | B2: =_xlfn.XLOOKUP(A2,'Do podmianki'!A:A,'Do podmianki'!B:B,K2) -> 40.2 | C2: 20.1 | I2: =_xlfn.XLOOKUP(A2,'Do podmianki'!A:A,'Do podmianki'!B:B,Generators!B2) -> 40.2 | K2: 40.2 | L2: 177.1 | O2: 47.480621 | P2: 13.809848 | U2: 40.102177 | V2: 135.5 | X2: 135.5 | Y2: -1 | Z2: -135.5 | AA2: 2.2 | AB2: 23.700001 | AC2: 76.400002 | AD2: 135.5 | AE2: 135.5 | AF2: -48.700001 | AG2: -111.7 | AH2: -7.1 | AI2: 135.5 | AJ2: -17.4 | AK2: -10.6 | AL2: -37.099998 | AM2: -17.6 | AN2: -14.7 | AO2: 3.4 | AP2: -5.1 | AQ2: 135.5 | AR2: -16.4 | AS2: -4.5 | AT2: 135.5 | AU2: -11.1 | AV2: 116.8 | AW2: 113.5 | AX2: -9.8 | AY2: -17 | AZ2: -36.900002 | BA2: -135.5 | BB2: 135.5 | BC2: 113 | BD2: 4 | BE2: 120.5 | BF2: 78.800003 | BG2: -135.5 | BH2: -135.5 | BI2: 119.7 | BJ2: -126.7 | BK2: 135.5 | BL2: -78.5 | BM2: 120.2 | BN2: -113.7 | BO2: -135.5 | BP2: 2.1 | BQ2: 9.7 | BR2: -135.5 | BS2: -135.5 | BT2: 121 | BU2: -8 | BV2: -3.1 | BW2: -2 | BX2: 135.5 | BY2: -40.599998 | BZ2: -7.4 | CA2: 40.599998 | CB2: 39.299999 | CC2: 53.5 | CD2: -135.5 | CE2: 25.799999 | CF2: 0.7 | CG2: -6.8 | CH2: -135.5 | CI2: 0.8 | CJ2: 1
A3: Gen10 | B3: =_xlfn.XLOOKUP(A3,'Do podmianki'!A:A,'Do podmianki'!B:B,K3) -> 30.5 | C3: -1.2 | I3: =_xlfn.XLOOKUP(A3,'Do podmianki'!A:A,'Do podmianki'!B:B,Generators!B3) -> 30.5 | K3: 30.5 | L3: -1.2 | O3: 29.77479 | P3: 3.7075994 | U3: 28.530404 | V3: -1
A4: Gen10029 | B4: =_xlfn.XLOOKUP(A4,'Do podmianki'!A:A,'Do podmianki'!B:B,K4) -> 51.7 | C4: -25.85 | I4: =_xlfn.XLOOKUP(A4,'Do podmianki'!A:A,'Do podmianki'!B:B,Generators!B4) -> 51.7 | K4: 51.7 | L4: -107.1 | O4: 53.949558 | P4: 10.954925 | U4: 53.927509 | V4: -135.5
A5: Gen108 | B5: =_xlfn.XLOOKUP(A5,'Do podmianki'!A:A,'Do podmianki'!B:B,K5) -> 42.8 | C5: 11.9 | I5: =_xlfn.XLOOKUP(A5,'Do podmianki'!A:A,'Do podmianki'!B:B,Generators!B5) -> 42.8 | K5: 42.8 | L5: 11.9 | O5: 41.749512 | P5: 8.4776 | U5: 33.318725 | V5: 2.2
A6: Gen11 | B6: =_xlfn.XLOOKUP(A6,'Do podmianki'!A:A,'Do podmianki'!B:B,K6) -> 22.9 | C6: 11.45 | I6: =_xlfn.XLOOKUP(A6,'Do podmianki'!A:A,'Do podmianki'!B:B,Generators!B6) -> 22.9 | K6: 22.9 | L6: 59.1 | O6: 30.47617 | P6: 6.1884503 | U6: 14.664228 | V6: 23.700001
A7: Gen119 | B7: =_xlfn.XLOOKUP(A7,'Do podmianki'!A:A,'Do podmianki'!B:B,K7) -> 100.1 | C7: 50.05 | I7: =_xlfn.XLOOKUP(A7,'Do podmianki'!A:A,'Do podmianki'!B:B,Generators!B7) -> 100.1 | K7: 100.1 | L7: 88.5 | O7: 128.00129 | P7: 8.4461844 | U7: 95.315361 | V7: 76.400002
A8: Gen124 | B8: =_xlfn.XLOOKUP(A8,'Do podmianki'!A:A,'Do podmianki'!B:B,K8) -> 29.3 | C8: 14.65 | I8: =_xlfn.XLOOKUP(A8,'Do podmianki'!A:A,'Do podmianki'!B:B,Generators!B8) -> 29.3 | K8: 29.3 | L8: 142.5 | O8: 21.151521 | P8: 4.2949995 | U8: 20.825491 | V8: 135.5
A9: Gen125 | B9: 50 | C9: 25 | I9: =_xlfn.XLOOKUP(A9,'Do podmianki'!A:A,'Do podmianki'!B:B,Generators!B9) -> 50 | K9: 70.9 | L9: 230.3 | O9: 109.48239 | P9: 22.231348 | U9: 84.137733 | V9: 135.5
A10: Gen126 | B10: =_xlfn.XLOOKUP(A10,'Do podmianki'!A:A,'Do podmianki'!B:B,K10) -> 45.1 | C10: -22.55 | I10: =_xlfn.XLOOKUP(A10,'Do podmianki'!A:A,'Do podmianki'!B:B,Generators!B10) -> 45.1 | K10: 45.1 | L10: -130.4 | O10: 35.789719 | P10: 7.2674124 | U10: 52.139011 | V10: -48.700001
A11: Gen130 | B11: =_xlfn.XLOOKUP(A11,'Do podmianki'!A:A,'Do podmianki'!B:B,K11) -> 32.7 | C11: -16.35 | I11: =_xlfn.XLOOKUP(A11,'Do podmianki'!A:A,'Do podmianki'!B:B,Generators!B11) -> 32.7 | K11: 32.7 | L11: -124.2 | O11: 37.960027 | P11: 7.7081122 | U11: 25.5459 | V11: -111.7
A12: Gen138 | B12: =_xlfn.XLOOKUP(A12,'Do podmianki'!A:A,'Do podmianki'!B:B,K12) -> 3.6 | C12: -1.8 | I12: =_xlfn.XLOOKUP(A12,'Do podmianki'!A:A,'Do podmianki'!B:B,Generators!B12) -> 3.6 | K12: 3.6 | L12: -7.4 | O12: 2.639432 | P12: 0.53595953 | U12: 4.105669 | V12: -7.0999999
A13: Gen139 | B13: 100 | C13: 50 | I13: =_xlfn.XLOOKUP(A13,'Do podmianki'!A:A,'Do podmianki'!B:B,Generators!B13) -> 100 | K13: 196.7 | L13: 144.4 | O13: 189.37579 | P13: 0.017326624 | U13: 174.9729 | V13: 135.5
A14: Gen141 | B14: 230 | C14: -18.3 | I14: =_xlfn.XLOOKUP(A14,'Do podmianki'!A:A,'Do podmianki'!B:B,Generators!B14) -> 230 | K14: 302.6 | L14: -18.3 | O14: 421.89191 | P14: 0.063983367 | U14: 393.34641 | V14: -17.4
A15: Gen143 | B15: =_xlfn.XLOOKUP(A15,'Do podmianki'!A:A,'Do podmianki'!B:B,K15) -> 44.9 | C15: -22.45 | I15: =_xlfn.XLOOKUP(A15,'Do podmianki'!A:A,'Do podmianki'!B:B,Generators!B15) -> 44.9 | K15: 44.9 | L15: -61.8 | O15: 56.853371 | P15: 11.544569 | U15: 67.460548 | V15: -10.6
A16: Gen146 | B16: =_xlfn.XLOOKUP(A16,'Do podmianki'!A:A,'Do podmianki'!B:B,K16) -> 49.8 | C16: -19.6 | I16: =_xlfn.XLOOKUP(A16,'Do podmianki'!A:A,'Do podmianki'!B:B,Generators!B16) -> 49.8 | K16: 49.8 | L16: -19.6 | O16: 71.028419 | P16: 14.422936 | U16: 58.1689 | V16: -37.099998
A17: Gen147 | B17: =_xlfn.XLOOKUP(A17,'Do podmianki'!A:A,'Do podmianki'!B:B,K17) -> 13.1 | C17: -6.55 | I17: =_xlfn.XLOOKUP(A17,'Do podmianki'!A:A,'Do podmianki'!B:B,Generators!B17) -> 13.1 | K17: 13.1 | L17: -10.6 | O17: 14.62901 | P17: 2.9705472 | U17: 15.28991 | V17: -17.6
A18: Gen149 | B18: =_xlfn.XLOOKUP(A18,'Do podmianki'!A:A,'Do podmianki'!B:B,K18) -> 32.7 | C18: -12.9 | I18: =_xlfn.XLOOKUP(A18,'Do podmianki'!A:A,'Do podmianki'!B:B,Generators!B18) -> 32.7 | K18: 32.7 | L18: -12.9 | O18: 42.36969 | P18: 8.6035325 | U18: 27.81139 | V18: -14.7
A19: Gen152 | B19: =_xlfn.XLOOKUP(A19,'Do podmianki'!A:A,'Do podmianki'!B:B,K19) -> 17.9 | C19: -8.95 | I19: =_xlfn.XLOOKUP(A19,'Do podmianki'!A:A,'Do podmianki'!B:B,Generators!B19) -> 17.9 | K19: 17.9 | L19: -15.4 | O19: 19.463961 | P19: 3.9523259 | U19: 20.316219 | V19: 3.4000001
A20: Gen153 | B20: =_xlfn.XLOOKUP(A20,'Do podmianki'!A:A,'Do podmianki'!B:B,K20) -> 54.9 | C20: -19.6 | I20: =_xlfn.XLOOKUP(A20,'Do podmianki'!A:A,'Do podmianki'!B:B,Generators!B20) -> 54.9 | K20: 54.9 | L20: -19.6 | O20: 43.477249 | P20: 8.8284319 | U20: 50.183392 | V20: -5.0999999
A21: Gen156 | B21: =_xlfn.XLOOKUP(A21,'Do podmianki'!A:A,'Do podmianki'!B:B,K21) -> 30.5 | C21: 15.25 | I21: =_xlfn.XLOOKUP(A21,'Do podmianki'!A:A,'Do podmianki'!B:B,Generators!B21) -> 30.5 | K21: 30.5 | L21: 172.5 | O21: 23.70833 | P21: 4.8141817 | U21: 40.867119 | V21: 135.5
A22: Gen166 | B22: =_xlfn.XLOOKUP(A22,'Do podmianki'!A:A,'Do podmianki'!B:B,K22) -> 59.7 | C22: -20.1 | I22: =_xlfn.XLOOKUP(A22,'Do podmianki'!A:A,'Do podmianki'!B:B,Generators!B22) -> 59.7 | K22: 59.7 | L22: -20.1 | O22: 69.407288 | P22: 14.093751 | U22: 57.43491 | V22: -16.4
A23: Gen17 | B23: =_xlfn.XLOOKUP(A23,'Do podmianki'!A:A,'Do podmianki'!B:B,K23) -> 18.3 | C23: -9.15 | I23: =_xlfn.XLOOKUP(A23,'Do podmianki'!A:A,'Do podmianki'!B:B,Generators!B23) -> 18.3 | K23: 18.3 | L23: -17.3 | O23: 22.209221 | P23: 4.5097747 | U23: 19.851574 | V23: -4.5
A24: Gen170 | B24: =_xlfn.XLOOKUP(A24,'Do podmianki'!A:A,'Do podmianki'!B:B,K24) -> 44.3 | C24: 22.15 | I24: =_xlfn.XLOOKUP(A24,'Do podmianki'!A:A,'Do podmianki'!B:B,Generators!B24) -> 44.3 | K24: 44.3 | L24: 230.4 | O24: 42.277531 | P24: 8.5848188 | U24: 52.147442 | V24: 135.5
A25: Gen171 | B25: =_xlfn.XLOOKUP(A25,'Do podmianki'!A:A,'Do podmianki'!B:B,K25) -> 105.7 | C25: -13.1 | I25: =_xlfn.XLOOKUP(A25,'Do podmianki'!A:A,'Do podmianki'!B:B,Generators!B25) -> 105.7 | K25: 105.7 | L25: -13.1 | O25: 132.97928 | P25: 19.032194 | U25: 77.493439 | V25: -11.1
A26: Gen175 | B26: =_xlfn.XLOOKUP(A26,'Do podmianki'!A:A,'Do podmianki'!B:B,K26) -> 31.8 | C26: 15.9 | I26: =_xlfn.XLOOKUP(A26,'Do podmianki'!A:A,'Do podmianki'!B:B,Generators!B26) -> 31.8 | K26: 31.8 | L26: 230.4 | O26: 63.72681 | P26: 12.940281 | U26: 48.19503 | V26: 116.8
... A40: Gen230 | B40: =_xlfn.XLOOKUP(A40,'Do podmianki'!A:A,'Do podmianki'!B:B,K40) -> 10.7 | C40: -5.35 | I40: =_xlfn.XLOOKUP(A40,'Do podmianki'!A:A,'Do podmianki'!B:B,Generators!B40) -> 10.7 | K40: 10.7 | L40: -93.5 | O40: 13.39883 | P40: 2.7207485 | U40: 12.70044 | V40: -126.7
A41: Gen236 | B41: 100 | C41: 50 | I41: =_xlfn.XLOOKUP(A41,'Do podmianki'!A:A,'Do podmianki'!B:B,Generators!B41) -> 100 | K41: 118.8 | L41: 146.9 | O41: 157.0834 | P41: 31.897146 | U41: 161.09109 | V41: 135.5
A42: Gen238 | B42: =_xlfn.XLOOKUP(A42,'Do podmianki'!A:A,'Do podmianki'!B:B,K42) -> 55.7 | C42: -27.85 | I42: =_xlfn.XLOOKUP(A42,'Do podmianki'!A:A,'Do podmianki'!B:B,Generators!B42) -> 55.7 | K42: 55.7 | L42: -73.9 | O42: 50.850288 | P42: 10.325591 | U42: 40.93959 | V42: -78.5
A43: Gen239 | B43: =_xlfn.XLOOKUP(A43,'Do podmianki'!A:A,'Do podmianki'!B:B,K43) -> 43.2 | C43: 21.6 | I43: =_xlfn.XLOOKUP(A43,'Do podmianki'!A:A,'Do podmianki'!B:B,Generators!B43) -> 43.2 | K43: 43.2 | L43: 121.2 | O43: 40.743568 | P43: 8.2733343 | U43: 40.680168 | V43: 120.2
A44: Gen24 | B44: 70 | C44: -35.4 | I44: =_xlfn.XLOOKUP(A44,'Do podmianki'!A:A,'Do podmianki'!B:B,Generators!B44) -> 70 | K44: 70.8 | L44: -96.9 | O44: 88.186836 | P44: 17.907101 | U44: 68.832093 | V44: -113.7
A45: Gen241 | B45: =_xlfn.XLOOKUP(A45,'Do podmianki'!A:A,'Do podmianki'!B:B,K45) -> 47.8 | C45: -23.9 | I45: =_xlfn.XLOOKUP(A45,'Do podmianki'!A:A,'Do podmianki'!B:B,Generators!B45) -> 47.8 | K45: 47.8 | L45: -98.5 | O45: -484.22675 | P45: -98.326435 | U45: 7.498323 | V45: -135.5
A46: Gen242 | B46: =_xlfn.XLOOKUP(A46,'Do podmianki'!A:A,'Do podmianki'!B:B,K46) -> 46.9 | C46: 1.1 | I46: =_xlfn.XLOOKUP(A46,'Do podmianki'!A:A,'Do podmianki'!B:B,Generators!B46) -> 46.9 | K46: 46.9 | L46: 1.1 | O46: 38.784821 | P46: 7.8755938 | U46: 38.392891 | V46: 2.0999999
A47: Gen243 | B47: 100 | C47: 8.5 | I47: =_xlfn.XLOOKUP(A47,'Do podmianki'!A:A,'Do podmianki'!B:B,Generators!B47) -> 100 | K47: 142.1 | L47: 8.5 | O47: 132.5056 | P47: 26.90641 | U47: 136.3705 | V47: 9.6999998
A48: Gen3 | B48: 70 | C48: -71.75 | I48: =_xlfn.XLOOKUP(A48,'Do podmianki'!A:A,'Do podmianki'!B:B,Generators!B48) -> 70 | K48: 143.5 | L48: -98.3 | O48: 168.8136 | P48: 33.16901 | U48: 93.172719 | V48: -135.5
A49: Gen372 | B49: 90 | C49: -11.15 | I49: =_xlfn.XLOOKUP(A49,'Do podmianki'!A:A,'Do podmianki'!B:B,Generators!B49) -> 90 | K49: 22.3 | L49: -100.6 | O49: 17.33452 | P49: 3.5199244 | U49: 9.277369 | V49: -135.5
A50: Gen44 | B50: =_xlfn.XLOOKUP(A50,'Do podmianki'!A:A,'Do podmianki'!B:B,K50) -> 26.8 | C50: 13.4 | I50: =_xlfn.XLOOKUP(A50,'Do podmianki'!A:A,'Do podmianki'!B:B,Generators!B50) -> 26.8 | K50: 26.8 | L50: 128.1 | O50: 22.67919 | P50: 4.6052059 | U50: 22.744517 | V50: 121
A51: Gen45 | B51: 70 | C51: -18.75 | I51: =_xlfn.XLOOKUP(A51,'Do podmianki'!A:A,'Do podmianki'!B:B,Generators!B51) -> 70 | K51: 37.5 | L51: -79.9 | O51: 51.239761 | P51: 10.404677 | U51: 36.710449 | V51: -8
A52: Gen46 | B52: 90 | C52: -11.15
A53: Gen49 | B53: =_xlfn.XLOOKUP(A53,'Do podmianki'!A:A,'Do podmianki'!B:B,K53) -> 53.3 | C53: -16.9 | I53: =_xlfn.XLOOKUP(A53,'Do podmianki'!A:A,'Do podmianki'!B:B,Generators!B53) -> 53.3 | K53: 53.3 | L53: -16.9 | O53: 64.999779 | P53: 13.198768 | U53: 52.172731 | V53: -3.0999999
...

Sheet PV
A1: name | B1: P | C1: Q | K1: Wyjściowe
A2: PV1 | B2: =_xlfn.XLOOKUP(A2,'Do podmianki'!A:A,'Do podmianki'!B:B,K2) -> 0 | C2: 0 | K2: 1e-10 | L2: 0
A3: PV10 | B3: =_xlfn.XLOOKUP(A3,'Do podmianki'!A:A,'Do podmianki'!B:B,K3) -> 0 | C3: 0 | K3: 1e-10 | L3: 0
A4: PV100 | B4: =_xlfn.XLOOKUP(A4,'Do podmianki'!A:A,'Do podmianki'!B:B,K4) -> 0 | C4: 0 | K4: 1e-10 | L4: 0
A5: PV102 | B5: =_xlfn.XLOOKUP(A5,'Do podmianki'!A:A,'Do podmianki'!B:B,K5) -> 0 | C5: 0 | K5: 1e-10 | L5: 0
A6: PV103 | B6: =_xlfn.XLOOKUP(A6,'Do podmianki'!A:A,'Do podmianki'!B:B,K6) -> 0 | C6: 0 | K6: 1e-10 | L6: 0
A7: PV104 | B7: =_xlfn.XLOOKUP(A7,'Do podmianki'!A:A,'Do podmianki'!B:B,K7) -> 0 | C7: 0 | K7: 1e-10 | L7: 0
A8: PV105 | B8: =_xlfn.XLOOKUP(A8,'Do podmianki'!A:A,'Do podmianki'!B:B,K8) -> 0 | C8: 0 | K8: 1e-10 | L8: 0
A9: PV107 | B9: =_xlfn.XLOOKUP(A9,'Do podmianki'!A:A,'Do podmianki'!B:B,K9) -> 0 | C9: 0 | K9: 1e-10 | L9: 0
A10: PV108 | B10: =_xlfn.XLOOKUP(A10,'Do podmianki'!A:A,'Do podmianki'!B:B,K10) -> 0 | C10: 0 | K10: 1e-10 | L10: 0
A11: PV109 | B11: =_xlfn.XLOOKUP(A11,'Do podmianki'!A:A,'Do podmianki'!B:B,K11) -> 0 | C11: 0 | K11: 1e-10 | L11: 0
A12: PV11 | B12: =_xlfn.XLOOKUP(A12,'Do podmianki'!A:A,'Do podmianki'!B:B,K12) -> 0 | C12: 0 | K12: 1e-10 | L12: 0
A13: PV110 | B13: =_xlfn.XLOOKUP(A13,'Do podmianki'!A:A,'Do podmianki'!B:B,K13) -> 0 | C13: 0 | K13: 1e-10 | L13: 0
... A108: PV99 | B108: =_xlfn.XLOOKUP(A108,'Do podmianki'!A:A,'Do podmianki'!B:B,K108) -> 0 | C108: 0 | K108: 1e-10 | L108: 0

Sheet StatGen
A1: name | B1: P | C1: Q | K1: Wyjściowe
A2: FW.10 | B2: =_xlfn.XLOOKUP(A2,'Do podmianki'!A:A,'Do podmianki'!B:B,K2) -> 0 | C2: =_xlfn.XLOOKUP(A2,'Do podmianki'!A:A,'Do podmianki'!C:C,L2) -> 0 | K2: 0 | L2: 0
A3: FW.13 | B3: =_xlfn.XLOOKUP(A3,'Do podmianki'!A:A,'Do podmianki'!B:B,K3) -> 0 | C3: =_xlfn.XLOOKUP(A3,'Do podmianki'!A:A,'Do podmianki'!C:C,L3) -> 0 | K3: 0 | L3: 0
A4: FW.20 | B4: =_xlfn.XLOOKUP(A4,'Do podmianki'!A:A,'Do podmianki'!B:B,K4) -> 0 | C4: =_xlfn.XLOOKUP(A4,'Do podmianki'!A:A,'Do podmianki'!C:C,L4) -> 0 | K4: 0 | L4: 0
A5: FW.21 | B5: =_xlfn.XLOOKUP(A5,'Do podmianki'!A:A,'Do podmianki'!B:B,K5) -> 0 | C5: =_xlfn.XLOOKUP(A5,'Do podmianki'!A:A,'Do podmianki'!C:C,L5) -> 0 | K5: 0 | L5: 0
A6: FW.7 | B6: =_xlfn.XLOOKUP(A6,'Do podmianki'!A:A,'Do podmianki'!B:B,K6) -> 0 | C6: =_xlfn.XLOOKUP(A6,'Do podmianki'!A:A,'Do podmianki'!C:C,L6) -> 0 | K6: 0 | L6: 0
A7: FW.11 | B7: =_xlfn.XLOOKUP(A7,'Do podmianki'!A:A,'Do podmianki'!B:B,K7) -> 0 | C7: =_xlfn.XLOOKUP(A7,'Do podmianki'!A:A,'Do podmianki'!C:C,L7) -> 0 | K7: 0 | L7: 0
A8: FW.5 | B8: =_xlfn.XLOOKUP(A8,'Do podmianki'!A:A,'Do podmianki'!B:B,K8) -> 0 | C8: =_xlfn.XLOOKUP(A8,'Do podmianki'!A:A,'Do podmianki'!C:C,L8) -> 0 | K8: 0 | L8: 0
A9: FW.6 | B9: =_xlfn.XLOOKUP(A9,'Do podmianki'!A:A,'Do podmianki'!B:B,K9) -> 0 | C9: =_xlfn.XLOOKUP(A9,'Do podmianki'!A:A,'Do podmianki'!C:C,L9) -> 0 | K9: 0 | L9: 0
A10: FW.8 | B10: =_xlfn.XLOOKUP(A10,'Do podmianki'!A:A,'Do podmianki'!B:B,K10) -> 0 | C10: =_xlfn.XLOOKUP(A10,'Do podmianki'!A:A,'Do podmianki'!C:C,L10) -> 0 | K10: 0 | L10: 0
A11: FW.14 | B11: =_xlfn.XLOOKUP(A11,'Do podmianki'!A:A,'Do podmianki'!B:B,K11) -> 0 | C11: =_xlfn.XLOOKUP(A11,'Do podmianki'!A:A,'Do podmianki'!C:C,L11) -> 0 | K11: 0 | L11: 0
A12: FW.2 | B12: =_xlfn.XLOOKUP(A12,'Do podmianki'!A:A,'Do podmianki'!B:B,K12) -> 0 | C12: =_xlfn.XLOOKUP(A12,'Do podmianki'!A:A,'Do podmianki'!C:C,L12) -> 0 | K12: 0 | L12: 0
A13: FW.9 | B13: =_xlfn.XLOOKUP(A13,'Do podmianki'!A:A,'Do podmianki'!B:B,K13) -> 0 | C13: =_xlfn.XLOOKUP(A13,'Do podmianki'!A:A,'Do podmianki'!C:C,L13) -> 0 | K13: 0 | L13: 0
... A134: ES110 | B134: =_xlfn.XLOOKUP(A134,'Do podmianki'!A:A,'Do podmianki'!B:B,K134) -> 0 | C134: =_xlfn.XLOOKUP(A134,'Do podmianki'!A:A,'Do podmianki'!C:C,L134) -> 0 | K134: 0 | L134: 0
A135: GenSta1 | B135: =_xlfn.XLOOKUP(A135,'Do podmianki'!A:A,'Do podmianki'!B:B,Q135) -> 47.147231 | C135: =_xlfn.XLOOKUP($P135,Generators!$A:$A,Generators!C:C) -> 20.1 | P135: Gen1 | Q135: =_xlfn.XLOOKUP($P135,Generators!$A:$A,Generators!B:B) -> 40.2 | R135: =_xlfn.XLOOKUP($P135,Generators!$A:$A,Generators!C:C) -> 20.1
A136: GenSta10 | B136: =_xlfn.XLOOKUP($P136,Generators!$A:$A,Generators!B:B) -> 30.5 | C136: =_xlfn.XLOOKUP($P136,Generators!$A:$A,Generators!C:C) -> -1.2 | P136: Gen10 | Q136: =_xlfn.XLOOKUP($P136,Generators!$A:$A,Generators!B:B) -> 30.5 | R136: =_xlfn.XLOOKUP($P136,Generators!$A:$A,Generators!C:C) -> -1.2
A137: GenSta108 | B137: =_xlfn.XLOOKUP($P137,Generators!$A:$A,Generators!B:B) -> 42.8 | C137: =_xlfn.XLOOKUP($P137,Generators!$A:$A,Generators!C:C) -> 11.9 | P137: Gen108 | Q137: =_xlfn.XLOOKUP($P137,Generators!$A:$A,Generators!B:B) -> 42.8 | R137: =_xlfn.XLOOKUP($P137,Generators!$A:$A,Generators!C:C) -> 11.9
A138: GenSta11 | B138: =_xlfn.XLOOKUP($P138,Generators!$A:$A,Generators!B:B) -> 22.9 | C138: =_xlfn.XLOOKUP($P138,Generators!$A:$A,Generators!C:C) -> 11.45 | P138: Gen11 | Q138: =_xlfn.XLOOKUP($P138,Generators!$A:$A,Generators!B:B) -> 22.9 | R138: =_xlfn.XLOOKUP($P138,Generators!$A:$A,Generators!C:C) -> 11.45
A139: GenSta17 | B139: =_xlfn.XLOOKUP($P139,Generators!$A:$A,Generators!B:B) -> 18.3 | C139: =_xlfn.XLOOKUP($P139,Generators!$A:$A,Generators!C:C) -> -9.15 | P139: Gen17 | Q139: =_xlfn.XLOOKUP($P139,Generators!$A:$A,Generators!B:B) -> 18.3 | R139: =_xlfn.XLOOKUP($P139,Generators!$A:$A,Generators!C:C) -> -9.15
A140: GenSta2 | B140: =_xlfn.XLOOKUP($P140,Generators!$A:$A,Generators!B:B) -> 66.9 | C140: =_xlfn.XLOOKUP($P140,Generators!$A:$A,Generators!C:C) -> 33.45 | P140: Gen2 | Q140: =_xlfn.XLOOKUP($P140,Generators!$A:$A,Generators!B:B) -> 66.9 | R140: =_xlfn.XLOOKUP($P140,Generators!$A:$A,Generators!C:C) -> 33.45
A141: GenSta20 | B141: =_xlfn.XLOOKUP($P141,Generators!$A:$A,Generators!B:B) -> 30.9 | C141: =_xlfn.XLOOKUP($P141,Generators!$A:$A,Generators!C:C) -> 15.45 | P141: Gen20 | Q141: =_xlfn.XLOOKUP($P141,Generators!$A:$A,Generators!B:B) -> 30.9 | R141: =_xlfn.XLOOKUP($P141,Generators!$A:$A,Generators!C:C) -> 15.45
A142: GenSta23 | B142: =_xlfn.XLOOKUP($P142,Generators!$A:$A,Generators!B:B) -> 11.2 | C142: =_xlfn.XLOOKUP($P142,Generators!$A:$A,Generators!C:C) -> 5.6 | P142: Gen23 | Q142: =_xlfn.XLOOKUP($P142,Generators!$A:$A,Generators!B:B) -> 11.2 | R142: =_xlfn.XLOOKUP($P142,Generators!$A:$A,Generators!C:C) -> 5.6
A143: GenSta24 | B143: =_xlfn.XLOOKUP($P143,Generators!$A:$A,Generators!B:B) -> 70 | C143: =_xlfn.XLOOKUP($P143,Generators!$A:$A,Generators!C:C) -> -35.4 | P143: Gen24 | Q143: =_xlfn.XLOOKUP($P143,Generators!$A:$A,Generators!B:B) -> 70 | R143: =_xlfn.XLOOKUP($P143,Generators!$A:$A,Generators!C:C) -> -35.4
A144: GenSta3 | B144: =_xlfn.XLOOKUP($P144,Generators!$A:$A,Generators!B:B) -> 70 | C144: =_xlfn.XLOOKUP($P144,Generators!$A:$A,Generators!C:C) -> -71.75 | P144: Gen3 | Q144: =_xlfn.XLOOKUP($P144,Generators!$A:$A,Generators!B:B) -> 70 | R144: =_xlfn.XLOOKUP($P144,Generators!$A:$A,Generators!C:C) -> -71.75
A145: GenSta372 | B145: =_xlfn.XLOOKUP($P145,Generators!$A:$A,Generators!B:B) -> 90 | C145: =_xlfn.XLOOKUP($P145,Generators!$A:$A,Generators!C:C) -> -11.15 | P145: Gen372 | Q145: =_xlfn.XLOOKUP($P145,Generators!$A:$A,Generators!B:B) -> 90 | R145: =_xlfn.XLOOKUP($P145,Generators!$A:$A,Generators!C:C) -> -11.15
A146: GenSta44 | B146: =_xlfn.XLOOKUP($P146,Generators!$A:$A,Generators!B:B) -> 26.8 | C146: =_xlfn.XLOOKUP($P146,Generators!$A:$A,Generators!C:C) -> 13.4 | P146: Gen44 | Q146: =_xlfn.XLOOKUP($P146,Generators!$A:$A,Generators!B:B) -> 26.8 | R146: =_xlfn.XLOOKUP($P146,Generators!$A:$A,Generators!C:C) -> 13.4
A147: GenSta45 | B147: =_xlfn.XLOOKUP($P147,Generators!$A:$A,Generators!B:B) -> 70 | C147: =_xlfn.XLOOKUP($P147,Generators!$A:$A,Generators!C:C) -> -18.75 | P147: Gen45 | Q147: =_xlfn.XLOOKUP($P147,Generators!$A:$A,Generators!B:B) -> 70 | R147: =_xlfn.XLOOKUP($P147,Generators!$A:$A,Generators!C:C) -> -18.75
A148: GenSta49 | B148: =_xlfn.XLOOKUP($P148,Generators!$A:$A,Generators!B:B) -> 53.3 | C148: =_xlfn.XLOOKUP($P148,Generators!$A:$A,Generators!C:C) -> -16.9 | P148: Gen49 | Q148: =_xlfn.XLOOKUP($P148,Generators!$A:$A,Generators!B:B) -> 53.3 | R148: =_xlfn.XLOOKUP($P148,Generators!$A:$A,Generators!C:C) -> -16.9
A149: GenSta5 | B149: 33.8 | C149: -16.9
A150: GenSta55 | B150: =_xlfn.XLOOKUP($P150,Generators!$A:$A,Generators!B:B) -> 62 | C150: =_xlfn.XLOOKUP($P150,Generators!$A:$A,Generators!C:C) -> -4.6 | P150: Gen55 | Q150: =_xlfn.XLOOKUP($P150,Generators!$A:$A,Generators!B:B) -> 62 | R150: =_xlfn.XLOOKUP($P150,Generators!$A:$A,Generators!C:C) -> -4.6
A151: GenSta57 | B151: =_xlfn.XLOOKUP($P151,Generators!$A:$A,Generators!B:B) -> 18.9 | C151: =_xlfn.XLOOKUP($P151,Generators!$A:$A,Generators!C:C) -> -2.7 | P151: Gen57 | Q151: =_xlfn.XLOOKUP($P151,Generators!$A:$A,Generators!B:B) -> 18.9 | R151: =_xlfn.XLOOKUP($P151,Generators!$A:$A,Generators!C:C) -> -2.7
A152: GenSta61 | B152: =_xlfn.XLOOKUP($P152,Generators!$A:$A,Generators!B:B) -> 8 | C152: =_xlfn.XLOOKUP($P152,Generators!$A:$A,Generators!C:C) -> 4 | P152: Gen61 | Q152: =_xlfn.XLOOKUP($P152,Generators!$A:$A,Generators!B:B) -> 8 | R152: =_xlfn.XLOOKUP($P152,Generators!$A:$A,Generators!C:C) -> 4
A153: GenSta62 | B153: =_xlfn.XLOOKUP($P153,Generators!$A:$A,Generators!B:B) -> 70 | C153: =_xlfn.XLOOKUP($P153,Generators!$A:$A,Generators!C:C) -> -25.4 | P153: Gen62 | Q153: =_xlfn.XLOOKUP($P153,Generators!$A:$A,Generators!B:B) -> 70 | R153: =_xlfn.XLOOKUP($P153,Generators!$A:$A,Generators!C:C) -> -25.4
A154: GenSta63 | B154: =_xlfn.XLOOKUP($P154,Generators!$A:$A,Generators!B:B) -> 33.8 | C154: =_xlfn.XLOOKUP($P154,Generators!$A:$A,Generators!C:C) -> -16.9 | P154: Gen63 | Q154: =_xlfn.XLOOKUP($P154,Generators!$A:$A,Generators!B:B) -> 33.8 | R154: =_xlfn.XLOOKUP($P154,Generators!$A:$A,Generators!C:C) -> -16.9
A155: GenSta7039 | B155: =_xlfn.XLOOKUP($P155,Generators!$A:$A,Generators!B:B) -> 90 | C155: =_xlfn.XLOOKUP($P155,Generators!$A:$A,Generators!C:C) -> -8.6 | P155: Gen7039 | Q155: =_xlfn.XLOOKUP($P155,Generators!$A:$A,Generators!B:B) -> 90 | R155: =_xlfn.XLOOKUP($P155,Generators!$A:$A,Generators!C:C) -> -8.6
A156: GenSta71 | B156: =_xlfn.XLOOKUP($P156,Generators!$A:$A,Generators!B:B) -> 80 | C156: =_xlfn.XLOOKUP($P156,Generators!$A:$A,Generators!C:C) -> 11.4 | P156: Gen71 | Q156: =_xlfn.XLOOKUP($P156,Generators!$A:$A,Generators!B:B) -> 80 | R156: =_xlfn.XLOOKUP($P156,Generators!$A:$A,Generators!C:C) -> 11.4
A157: GenSta76 | B157: =_xlfn.XLOOKUP($P157,Generators!$A:$A,Generators!B:B) -> 63.5 | C157: =_xlfn.XLOOKUP($P157,Generators!$A:$A,Generators!C:C) -> 31.75 | P157: Gen76 | Q157: =_xlfn.XLOOKUP($P157,Generators!$A:$A,Generators!B:B) -> 63.5 | R157: =_xlfn.XLOOKUP($P157,Generators!$A:$A,Generators!C:C) -> 31.75
A158: GenSta772 | B158: =_xlfn.XLOOKUP($P158,Generators!$A:$A,Generators!B:B) -> 90 | C158: =_xlfn.XLOOKUP($P158,Generators!$A:$A,Generators!C:C) -> -20.3 | P158: Gen772 | Q158: =_xlfn.XLOOKUP($P158,Generators!$A:$A,Generators!B:B) -> 90 | R158: =_xlfn.XLOOKUP($P158,Generators!$A:$A,Generators!C:C) -> -20.3
A159: GenSta77 | B159: 33.8 | C159: -16.9
A160: GenSta79 | B160: 33.8 | C160: -16.9
...

Sheet ExportConfig
A1: Element_Type | B1: Column_Name | C1: PF_Attribute | D1: Unit | E1: Format
A2: ElmTerm | B2: Nazwa | C2: loc_name | D2: - | E2: str
A3: ElmTerm | B3: Un [kV] | C3: uknom | D3: kV | E3: .2f
A4: ElmTerm | B4: U [kV] | C4: m:Ul | D4: kV | E4: .3f
A5: ElmTerm | B5: U [p. u.] | C5: m:u | D5: p.u. | E5: .4f
A6: ElmTerm | B6: Kąt [°] | C6: m:phiu | D6: ° | E6: .2f
A7: ElmLne | B7: Linia | C7: loc_name | D7: - | E7: str
A8: ElmLne | B8: Obciążenie [%] | C8: c:loading | D8: % | E8: .2f
A9: ElmLne | B9: Nominal Current | C9: c:curnom | D9: kA | E9: .3f
A10: ElmLne | B10: Maximum Current | C10: c:Imax | D10: kA | E10: .3f
A11: ElmTr3 | B11: Transformator | C11: loc_name | D11: - | E11: str
A12: ElmTr3 | B12: Obciążenie [%] | C12: c:loading | D12: . 2f
A13: ElmTr3 | B13: Odczep | C13: c:n3tap_h | D13: - | E13: .0f

Sheet Rekonfiguracja
A1: Line_Name | B1: Can_Disable | C1: Priority | D1: Notes | H1: Parameter | I1: Value | J1: Description
A2: 1.73 | B2: =_xlfn.XLOOKUP($N2,$P$2:$P$13,$Q$2:$Q$13) -> 1 | C2: =_xlfn.XLOOKUP($N2,$P$2:$P$13,$R$2:$R$13) -> 1 | D2: =_xlfn.XLOOKUP($N2,$P$2:$P$13,$S$2:$S$13) -> Możliwa do wyłączenia | H2: Max_Lines_Out | I2: 4 | J2: Maksymalna liczba linii do wyłączenia jednocześnie | L2: Area 1-110kV | M2: 1.73 | N2: =_xlfn.XLOOKUP(M2,$I$8:$I$15,$J$8:$J$15,L2) -> Area 1-110kV | P2: Area 1-110kV | Q2: 1 | R2: 1 | S2: Możliwa do wyłączenia
A3: 10.13 | B3: =_xlfn.XLOOKUP($N3,$P$2:$P$13,$Q$2:$Q$13) -> 1 | C3: =_xlfn.XLOOKUP($N3,$P$2:$P$13,$R$2:$R$13) -> 1 | D3: =_xlfn.XLOOKUP($N3,$P$2:$P$13,$S$2:$S$13) -> Możliwa do wyłączenia | H3: Min_Lines_Out | I3: 1 | J3: Minimalna liczba (opcjonalne, domyślnie 1) | L3: Area 1-110kV | M3: 10.13 | N3: =_xlfn.XLOOKUP(M3,$I$8:$I$15,$J$8:$J$15,L3) -> Area 1-110kV | P3: Area 2-110kV | Q3: 0 | R3: - | S3: Obcy obszar
A4: 100.102 | B4: =_xlfn.XLOOKUP($N4,$P$2:$P$13,$Q$2:$Q$13) -> 1 | C4: =_xlfn.XLOOKUP($N4,$P$2:$P$13,$R$2:$R$13) -> 1 | D4: =_xlfn.XLOOKUP($N4,$P$2:$P$13,$S$2:$S$13) -> Możliwa do wyłączenia | L4: Area 1-110kV | M4: 100.102 | N4: =_xlfn.XLOOKUP(M4,$I$8:$I$15,$J$8:$J$15,L4) -> Area 1-110kV | P4: Area 3-110kV | Q4: 0 | R4: - | S4: Obcy obszar
A5: 102.104 | B5: =_xlfn.XLOOKUP($N5,$P$2:$P$13,$Q$2:$Q$13) -> 1 | C5: =_xlfn.XLOOKUP($N5,$P$2:$P$13,$R$2:$R$13) -> 1 | D5: =_xlfn.XLOOKUP($N5,$P$2:$P$13,$S$2:$S$13) -> Możliwa do wyłączenia | L5: Area 1-110kV | M5: 102.104 | N5: =_xlfn.XLOOKUP(M5,$I$8:$I$15,$J$8:$J$15,L5) -> Area 1-110kV | P5: Wył | Q5: 0 | R5: - | S5: Linia wyłączona w n-1
A6: 102.33 | B6: =_xlfn.XLOOKUP($N6,$P$2:$P$13,$Q$2:$Q$13) -> 1 | C6: =_xlfn.XLOOKUP($N6,$P$2:$P$13,$R$2:$R$13) -> 1 | D6: =_xlfn.XLOOKUP($N6,$P$2:$P$13,$S$2:$S$13) -> Możliwa do wyłączenia | L6: Area 1-110kV | M6: 102.33 | N6: =_xlfn.XLOOKUP(M6,$I$8:$I$15,$J$8:$J$15,L6) -> Area 1-110kV | P6: Obs | Q6: 0 | R6: - | S6: Linia Obserwowana
A7: 102.98 | B7: =_xlfn.XLOOKUP($N7,$P$2:$P$13,$Q$2:$Q$13) -> 1 | C7: =_xlfn.XLOOKUP($N7,$P$2:$P$13,$R$2:$R$13) -> 1 | D7: =_xlfn.XLOOKUP($N7,$P$2:$P$13,$S$2:$S$13) -> Możliwa do wyłączenia | L7: Area 1-110kV | M7: 102.98 | N7: =_xlfn.XLOOKUP(M7,$I$8:$I$15,$J$8:$J$15,L7) -> Area 1-110kV | P7: - | Q7: 1 | R7: 2 | S7: Linia rezerwowa
A8: 10201.12 | B8: =_xlfn.XLOOKUP($N8,$P$2:$P$13,$Q$2:$Q$13) -> 0 | C8: =_xlfn.XLOOKUP($N8,$P$2:$P$13,$R$2:$R$13) -> - | D8: =_xlfn.XLOOKUP($N8,$P$2:$P$13,$S$2:$S$13) -> Obcy obszar | I8: 70.71 | J8: Wył | L8: Area 2-110kV | M8: 10201.12 | N8: =_xlfn.XLOOKUP(M8,$I$8:$I$15,$J$8:$J$15,L8) -> Area 2-110kV | P8: - | Q8: 1 | R8: 3 | S8: Niski priorytet
A9: 1024.175 | B9: =_xlfn.XLOOKUP($N9,$P$2:$P$13,$Q$2:$Q$13) -> 0 | C9: =_xlfn.XLOOKUP($N9,$P$2:$P$13,$R$2:$R$13) -> - | D9: =_xlfn.XLOOKUP($N9,$P$2:$P$13,$S$2:$S$13) -> Obcy obszar | G9: 5.73 | H9: 5.73 | J9: Obs | L9: Area 2-110kV | M9: 1024.175 | N9: =_xlfn.XLOOKUP(M9,$I$8:$I$15,$J$8:$J$15,L9) -> Area 2-110kV | P9: 220kV | Q9: 0 | R9: - | S9: NIE wyłączać - przesyłowa
A10: 1024.176 | B10: =_xlfn.XLOOKUP($N10,$P$2:$P$13,$Q$2:$Q$13) -> 0 | C10: =_xlfn.XLOOKUP($N10,$P$2:$P$13,$R$2:$R$13) -> - | D10: =_xlfn.XLOOKUP($N10,$P$2:$P$13,$S$2:$S$13) -> Obcy obszar | G10: 8.14 | H10: 1.73 | J10: Obs | L10: Area 2-110kV | M10: 1024.176 | N10: =_xlfn.XLOOKUP(M10,$I$8:$I$15,$J$8:$J$15,L10) -> Area 2-110kV | P10: 400kV | Q10: 0 | R10: - | S10: NIE wyłączać - przesyłowa
A11: 103.105 | B11: =_xlfn.XLOOKUP($N11,$P$2:$P$13,$Q$2:$Q$13) -> 1 | C11: =_xlfn.XLOOKUP($N11,$P$2:$P$13,$R$2:$R$13) -> 1 | D11: =_xlfn.XLOOKUP($N11,$P$2:$P$13,$S$2:$S$13) -> Możliwa do wyłączenia | G11: 73.71 | H11: 73.71 | J11: Obs | L11: Area 1-110kV | M11: 103.105 | N11: =_xlfn.XLOOKUP(M11,$I$8:$I$15,$J$8:$J$15,L11) -> Area 1-110kV
A12: 104.108 | B12: =_xlfn.XLOOKUP($N12,$P$2:$P$13,$Q$2:$Q$13) -> 1 | C12: =_xlfn.XLOOKUP($N12,$P$2:$P$13,$R$2:$R$13) -> 1 | D12: =_xlfn.XLOOKUP($N12,$P$2:$P$13,$S$2:$S$13) -> Możliwa do wyłączenia | G12: 175.173 | H12: 79.73 | J12: Obs | L12: Area 1-110kV | M12: 104.108 | N12: =_xlfn.XLOOKUP(M12,$I$8:$I$15,$J$8:$J$15,L12) -> Area 1-110kV
A13: 105.107 | B13: =_xlfn.XLOOKUP($N13,$P$2:$P$13,$Q$2:$Q$13) -> 1 | C13: =_xlfn.XLOOKUP($N13,$P$2:$P$13,$R$2:$R$13) -> 1 | D13: =_xlfn.XLOOKUP($N13,$P$2:$P$13,$S$2:$S$13) -> Możliwa do wyłączenia | G13: 173.172 | H13: 5.9 | J13: Obs | L13: Area 1-110kV | M13: 105.107 | N13: =_xlfn.XLOOKUP(M13,$I$8:$I$15,$J$8:$J$15,L13) -> Area 1-110kV
A14: 105.11 | B14: =_xlfn.XLOOKUP($N14,$P$2:$P$13,$Q$2:$Q$13) -> 1 | C14: =_xlfn.XLOOKUP($N14,$P$2:$P$13,$R$2:$R$13) -> 1 | D14: =_xlfn.XLOOKUP($N14,$P$2:$P$13,$S$2:$S$13) -> Możliwa do wyłączenia | G14: 35.77 | J14: Obs | L14: Area 1-110kV | M14: 105.11 | N14: =_xlfn.XLOOKUP(M14,$I$8:$I$15,$J$8:$J$15,L14) -> Area 1-110kV
A15: 107.99 | B15: =_xlfn.XLOOKUP($N15,$P$2:$P$13,$Q$2:$Q$13) -> 1 | C15: =_xlfn.XLOOKUP($N15,$P$2:$P$13,$R$2:$R$13) -> 1 | D15: =_xlfn.XLOOKUP($N15,$P$2:$P$13,$S$2:$S$13) -> Możliwa do wyłączenia | G15: 5.9 | J15: Obs | L15: Area 1-110kV | M15: 107.99 | N15: =_xlfn.XLOOKUP(M15,$I$8:$I$15,$J$8:$J$15,L15) -> Area 1-110kV
A16: 109.11 | B16: =_xlfn.XLOOKUP($N16,$P$2:$P$13,$Q$2:$Q$13) -> 1 | C16: =_xlfn.XLOOKUP($N16,$P$2:$P$13,$R$2:$R$13) -> 1 | D16: =_xlfn.XLOOKUP($N16,$P$2:$P$13,$S$2:$S$13) -> Możliwa do wyłączenia | L16: Area 1-110kV | M16: 109.11 | N16: =_xlfn.XLOOKUP(M16,$I$8:$I$15,$J$8:$J$15,L16) -> Area 1-110kV
A17: 109.113 | B17: =_xlfn.XLOOKUP($N17,$P$2:$P$13,$Q$2:$Q$13) -> 1 | C17: =_xlfn.XLOOKUP($N17,$P$2:$P$13,$R$2:$R$13) -> 1 | D17: =_xlfn.XLOOKUP($N17,$P$2:$P$13,$S$2:$S$13) -> Możliwa do wyłączenia | L17: Area 1-110kV | M17: 109.113 | N17: =_xlfn.XLOOKUP(M17,$I$8:$I$15,$J$8:$J$15,L17) -> Area 1-110kV
A18: 109.99 | B18: =_xlfn.XLOOKUP($N18,$P$2:$P$13,$Q$2:$Q$13) -> 1 | C18: =_xlfn.XLOOKUP($N18,$P$2:$P$13,$R$2:$R$13) -> 1 | D18: =_xlfn.XLOOKUP($N18,$P$2:$P$13,$S$2:$S$13) -> Możliwa do wyłączenia | L18: Area 1-110kV | M18: 109.99 | N18: =_xlfn.XLOOKUP(M18,$I$8:$I$15,$J$8:$J$15,L18) -> Area 1-110kV
A19: 11.1 | B19: =_xlfn.XLOOKUP($N19,$P$2:$P$13,$Q$2:$Q$13) -> 1 | C19: =_xlfn.XLOOKUP($N19,$P$2:$P$13,$R$2:$R$13) -> 1 | D19: =_xlfn.XLOOKUP($N19,$P$2:$P$13,$S$2:$S$13) -> Możliwa do wyłączenia | L19: Area 1-110kV | M19: 11.1 | N19: =_xlfn.XLOOKUP(M19,$I$8:$I$15,$J$8:$J$15,L19) -> Area 1-110kV
A20: 11.8 | B20: =_xlfn.XLOOKUP($N20,$P$2:$P$13,$Q$2:$Q$13) -> 1 | C20: =_xlfn.XLOOKUP($N20,$P$2:$P$13,$R$2:$R$13) -> 1 | D20: =_xlfn.XLOOKUP($N20,$P$2:$P$13,$S$2:$S$13) -> Możliwa do wyłączenia | L20: Area 1-110kV | M20: 11.8 | N20: =_xlfn.XLOOKUP(M20,$I$8:$I$15,$J$8:$J$15,L20) -> Area 1-110kV
A21: 11.9 | B21: =_xlfn.XLOOKUP($N21,$P$2:$P$13,$Q$2:$Q$13) -> 1 | C21: =_xlfn.XLOOKUP($N21,$P$2:$P$13,$R$2:$R$13) -> 1 | D21: =_xlfn.XLOOKUP($N21,$P$2:$P$13,$S$2:$S$13) -> Możliwa do wyłączenia | L21: Area 1-110kV | M21: 11.9 | N21: =_xlfn.XLOOKUP(M21,$I$8:$I$15,$J$8:$J$15,L21) -> Area 1-110kV
A22: 110.9001 | B22: =_xlfn.XLOOKUP($N22,$P$2:$P$13,$Q$2:$Q$13) -> 1 | C22: =_xlfn.XLOOKUP($N22,$P$2:$P$13,$R$2:$R$13) -> 1 | D22: =_xlfn.XLOOKUP($N22,$P$2:$P$13,$S$2:$S$13) -> Możliwa do wyłączenia | L22: Area 1-110kV | M22: 110.9001 | N22: =_xlfn.XLOOKUP(M22,$I$8:$I$15,$J$8:$J$15,L22) -> Area 1-110kV
A23: 112.11 | B23: =_xlfn.XLOOKUP($N23,$P$2:$P$13,$Q$2:$Q$13) -> 1 | C23: =_xlfn.XLOOKUP($N23,$P$2:$P$13,$R$2:$R$13) -> 1 | D23: =_xlfn.XLOOKUP($N23,$P$2:$P$13,$S$2:$S$13) -> Możliwa do wyłączenia | L23: Area 1-110kV | M23: 112.11 | N23: =_xlfn.XLOOKUP(M23,$I$8:$I$15,$J$8:$J$15,L23) -> Area 1-110kV
A24: 113.47 | B24: =_xlfn.XLOOKUP($N24,$P$2:$P$13,$Q$2:$Q$13) -> 1 | C24: =_xlfn.XLOOKUP($N24,$P$2:$P$13,$R$2:$R$13) -> 1 | D24: =_xlfn.XLOOKUP($N24,$P$2:$P$13,$S$2:$S$13) -> Możliwa do wyłączenia | L24: Area 1-110kV | M24: 113.47 | N24: =_xlfn.XLOOKUP(M24,$I$8:$I$15,$J$8:$J$15,L24) -> Area 1-110kV
A25: 114.109 | B25: =_xlfn.XLOOKUP($N25,$P$2:$P$13,$Q$2:$Q$13) -> 1 | C25: =_xlfn.XLOOKUP($N25,$P$2:$P$13,$R$2:$R$13) -> 1 | D25: =_xlfn.XLOOKUP($N25,$P$2:$P$13,$S$2:$S$13) -> Możliwa do wyłączenia | L25: Area 1-110kV | M25: 114.109 | N25: =_xlfn.XLOOKUP(M25,$I$8:$I$15,$J$8:$J$15,L25) -> Area 1-110kV
A26: 114.112 | B26: =_xlfn.XLOOKUP($N26,$P$2:$P$13,$Q$2:$Q$13) -> 1 | C26: =_xlfn.XLOOKUP($N26,$P$2:$P$13,$R$2:$R$13) -> 1 | D26: =_xlfn.XLOOKUP($N26,$P$2:$P$13,$S$2:$S$13) -> Możliwa do wyłączenia | L26: Area 1-110kV | M26: 114.112 | N26: =_xlfn.XLOOKUP(M26,$I$8:$I$15,$J$8:$J$15,L26) -> Area 1-110kV
A27: 115.121 | B27: =_xlfn.XLOOKUP($N27,$P$2:$P$13,$Q$2:$Q$13) -> 0 | C27: =_xlfn.XLOOKUP($N27,$P$2:$P$13,$R$2:$R$13) -> - | D27: =_xlfn.XLOOKUP($N27,$P$2:$P$13,$S$2:$S$13) -> Obcy obszar | L27: Area 2-110kV | M27: 115.121 | N27: =_xlfn.XLOOKUP(M27,$I$8:$I$15,$J$8:$J$15,L27) -> Area 2-110kV
... A329: 99.11 | B329: =_xlfn.XLOOKUP($N329,$P$2:$P$13,$Q$2:$Q$13) -> 1 | C329: =_xlfn.XLOOKUP($N329,$P$2:$P$13,$R$2:$R$13) -> 1 | D329: =_xlfn.XLOOKUP($N329,$P$2:$P$13,$S$2:$S$13) -> Możliwa do wyłączenia | L329: Area 1-110kV | M329: 99.11 | N329: =_xlfn.XLOOKUP(M329,$I$8:$I$15,$J$8:$J$15,L329) -> Area 1-110kV

Sheet Optymalizacja
A1: Element_Name | B1: Element_Type | C1: Attribute_P | D1: Pmin | E1: Pmax | F1: Attribute_Q | G1: Qmin | H1: Qmax
A2: GenSta44 | B2: =IF(A2="","",IF(ISNUMBER(SEARCH("GenSta",A2)),"ElmGenstat",IF(ISNUMBER(SEARCH("ES",A2)),"ElmGenstat",IF(ISNUMBER(SEARCH("Ld",A2)),"ElmLod","")))) -> ElmGenstat | C2: =IF(A2="","",IF(ISNUMBER(SEARCH("GenSta",A2)),"pgini",IF(ISNUMBER(SEARCH("ES",A2)),"pgini",IF(ISNUMBER(SEARCH("Ld",A2)),"plini","")))) -> pgini | D2: =IF(A2="","",IF(ISNUMBER(SEARCH("GenSta",A2)),0,IF(ISNUMBER(SEARCH("ES",A2)),-50*$L$3,IF(ISNUMBER(SEARCH("Ld",A2)),0.2*E2,"")))) -> 0 | E2: =IF(A2="","",IF(ISNUMBER(SEARCH("GenSta",A2)),100*$L$2,IF(ISNUMBER(SEARCH("ES",A2)),50*$L$3,IF(ISNUMBER(SEARCH("Ld",A2)),2*O2*$L$4,"")))) -> 100 | F2: =IF(A2="","",IF(ISNUMBER(SEARCH("GenSta",A2)),"qgini",IF(ISNUMBER(SEARCH("ES",A2)),"qgini",IF(ISNUMBER(SEARCH("Ld",A2)),"qlini","")))) -> qgini | G2: =IF(A2="","",IF(ISNUMBER(SEARCH("GenSta",A2)),-E2,IF(ISNUMBER(SEARCH("ES",A2)),D2,IF(ISNUMBER(SEARCH("Ld",A2)),-E2,"")))) -> -100 | H2: =IF(A2="","",IF(ISNUMBER(SEARCH("GenSta",A2)),E2,IF(ISNUMBER(SEARCH("ES",A2)),E2,IF(ISNUMBER(SEARCH("Ld",A2)),E2,"")))) -> 100 | I2: 1 | K2: mnożnik | L2: 1 | N2: =IF((_xlfn.XLOOKUP(A2,StatGen!A:A,StatGen!B:B," ")=0),(""),(_xlfn.IFNA(_xlfn.XLOOKUP(A2,StatGen!A:A,StatGen!B:B," "),""))) -> 26.8 | O2: =IF((_xlfn.XLOOKUP(A2,Loads!A:A,Loads!B:B," ")=0),(""),(_xlfn.IFNA(_xlfn.XLOOKUP(A2,Loads!A:A,Loads!B:B," "),""))) | S2: Gen1 | T2: ElmSym
A3: GenSta11 | B3: =IF(A3="","",IF(ISNUMBER(SEARCH("GenSta",A3)),"ElmGenstat",IF(ISNUMBER(SEARCH("ES",A3)),"ElmGenstat",IF(ISNUMBER(SEARCH("Ld",A3)),"ElmLod","")))) -> ElmGenstat | C3: =IF(A3="","",IF(ISNUMBER(SEARCH("GenSta",A3)),"pgini",IF(ISNUMBER(SEARCH("ES",A3)),"pgini",IF(ISNUMBER(SEARCH("Ld",A3)),"plini","")))) -> pgini | D3: =IF(A3="","",IF(ISNUMBER(SEARCH("GenSta",A3)),0,IF(ISNUMBER(SEARCH("ES",A3)),-50*$L$3,IF(ISNUMBER(SEARCH("Ld",A3)),0.2*E3,"")))) -> 0 | E3: =IF(A3="","",IF(ISNUMBER(SEARCH("GenSta",A3)),100*$L$2,IF(ISNUMBER(SEARCH("ES",A3)),50*$L$3,IF(ISNUMBER(SEARCH("Ld",A3)),2*O3*$L$4,"")))) -> 100 | F3: =IF(A3="","",IF(ISNUMBER(SEARCH("GenSta",A3)),"qgini",IF(ISNUMBER(SEARCH("ES",A3)),"qgini",IF(ISNUMBER(SEARCH("Ld",A3)),"qlini","")))) -> qgini | G3: =IF(A3="","",IF(ISNUMBER(SEARCH("GenSta",A3)),-E3,IF(ISNUMBER(SEARCH("ES",A3)),D3,IF(ISNUMBER(SEARCH("Ld",A3)),-E3,"")))) -> -100 | H3: =IF(A3="","",IF(ISNUMBER(SEARCH("GenSta",A3)),E3,IF(ISNUMBER(SEARCH("ES",A3)),E3,IF(ISNUMBER(SEARCH("Ld",A3)),E3,"")))) -> 100 | K3: mag | L3: 1 | N3: =IF((_xlfn.XLOOKUP(A3,StatGen!A:A,StatGen!B:B," ")=0),(""),(_xlfn.IFNA(_xlfn.XLOOKUP(A3,StatGen!A:A,StatGen!B:B," "),""))) -> 22.9 | O3: =IF((_xlfn.XLOOKUP(A3,Loads!A:A,Loads!B:B," ")=0),(""),(_xlfn.IFNA(_xlfn.XLOOKUP(A3,Loads!A:A,Loads!B:B," "),""))) | S3: Gen10 | T3: ElmSym
A4: GenSta92 | B4: =IF(A4="","",IF(ISNUMBER(SEARCH("GenSta",A4)),"ElmGenstat",IF(ISNUMBER(SEARCH("ES",A4)),"ElmGenstat",IF(ISNUMBER(SEARCH("Ld",A4)),"ElmLod","")))) -> ElmGenstat | C4: =IF(A4="","",IF(ISNUMBER(SEARCH("GenSta",A4)),"pgini",IF(ISNUMBER(SEARCH("ES",A4)),"pgini",IF(ISNUMBER(SEARCH("Ld",A4)),"plini","")))) -> pgini | D4: =IF(A4="","",IF(ISNUMBER(SEARCH("GenSta",A4)),0,IF(ISNUMBER(SEARCH("ES",A4)),-50*$L$3,IF(ISNUMBER(SEARCH("Ld",A4)),0.2*E4,"")))) -> 0 | E4: =IF(A4="","",IF(ISNUMBER(SEARCH("GenSta",A4)),100*$L$2,IF(ISNUMBER(SEARCH("ES",A4)),50*$L$3,IF(ISNUMBER(SEARCH("Ld",A4)),2*O4*$L$4,"")))) -> 100 | F4: =IF(A4="","",IF(ISNUMBER(SEARCH("GenSta",A4)),"qgini",IF(ISNUMBER(SEARCH("ES",A4)),"qgini",IF(ISNUMBER(SEARCH("Ld",A4)),"qlini","")))) -> qgini | G4: =IF(A4="","",IF(ISNUMBER(SEARCH("GenSta",A4)),-E4,IF(ISNUMBER(SEARCH("ES",A4)),D4,IF(ISNUMBER(SEARCH("Ld",A4)),-E4,"")))) -> -100 | H4: =IF(A4="","",IF(ISNUMBER(SEARCH("GenSta",A4)),E4,IF(ISNUMBER(SEARCH("ES",A4)),E4,IF(ISNUMBER(SEARCH("Ld",A4)),E4,"")))) -> 100 | K4: odb | L4: 1 | N4: =IF((_xlfn.XLOOKUP(A4,StatGen!A:A,StatGen!B:B," ")=0),(""),(_xlfn.IFNA(_xlfn.XLOOKUP(A4,StatGen!A:A,StatGen!B:B," "),""))) -> 1.2 | O4: =IF((_xlfn.XLOOKUP(A4,Loads!A:A,Loads!B:B," ")=0),(""),(_xlfn.IFNA(_xlfn.XLOOKUP(A4,Loads!A:A,Loads!B:B," "),""))) | S4: Gen108 | T4: ElmSym
A5: GenSta84 | B5: =IF(A5="","",IF(ISNUMBER(SEARCH("GenSta",A5)),"ElmGenstat",IF(ISNUMBER(SEARCH("ES",A5)),"ElmGenstat",IF(ISNUMBER(SEARCH("Ld",A5)),"ElmLod","")))) -> ElmGenstat | C5: =IF(A5="","",IF(ISNUMBER(SEARCH("GenSta",A5)),"pgini",IF(ISNUMBER(SEARCH("ES",A5)),"pgini",IF(ISNUMBER(SEARCH("Ld",A5)),"plini","")))) -> pgini | D5: =IF(A5="","",IF(ISNUMBER(SEARCH("GenSta",A5)),0,IF(ISNUMBER(SEARCH("ES",A5)),-50*$L$3,IF(ISNUMBER(SEARCH("Ld",A5)),0.2*E5,"")))) -> 0 | E5: =IF(A5="","",IF(ISNUMBER(SEARCH("GenSta",A5)),100*$L$2,IF(ISNUMBER(SEARCH("ES",A5)),50*$L$3,IF(ISNUMBER(SEARCH("Ld",A5)),2*O5*$L$4,"")))) -> 100 | F5: =IF(A5="","",IF(ISNUMBER(SEARCH("GenSta",A5)),"qgini",IF(ISNUMBER(SEARCH("ES",A5)),"qgini",IF(ISNUMBER(SEARCH("Ld",A5)),"qlini","")))) -> qgini | G5: =IF(A5="","",IF(ISNUMBER(SEARCH("GenSta",A5)),-E5,IF(ISNUMBER(SEARCH("ES",A5)),D5,IF(ISNUMBER(SEARCH("Ld",A5)),-E5,"")))) -> -100 | H5: =IF(A5="","",IF(ISNUMBER(SEARCH("GenSta",A5)),E5,IF(ISNUMBER(SEARCH("ES",A5)),E5,IF(ISNUMBER(SEARCH("Ld",A5)),E5,"")))) -> 100 | N5: =IF((_xlfn.XLOOKUP(A5,StatGen!A:A,StatGen!B:B," ")=0),(""),(_xlfn.IFNA(_xlfn.XLOOKUP(A5,StatGen!A:A,StatGen!B:B," "),""))) -> 77 | O5: =IF((_xlfn.XLOOKUP(A5,Loads!A:A,Loads!B:B," ")=0),(""),(_xlfn.IFNA(_xlfn.XLOOKUP(A5,Loads!A:A,Loads!B:B," "),""))) | S5: Gen11 | T5: ElmSym
A6: ES23 | B6: =IF(A6="","",IF(ISNUMBER(SEARCH("GenSta",A6)),"ElmGenstat",IF(ISNUMBER(SEARCH("ES",A6)),"ElmGenstat",IF(ISNUMBER(SEARCH("Ld",A6)),"ElmLod","")))) -> ElmGenstat | C6: =IF(A6="","",IF(ISNUMBER(SEARCH("GenSta",A6)),"pgini",IF(ISNUMBER(SEARCH("ES",A6)),"pgini",IF(ISNUMBER(SEARCH("Ld",A6)),"plini","")))) -> pgini | D6: =IF(A6="","",IF(ISNUMBER(SEARCH("GenSta",A6)),0,IF(ISNUMBER(SEARCH("ES",A6)),-50*$L$3,IF(ISNUMBER(SEARCH("Ld",A6)),0.2*E6,"")))) -> -50 | E6: =IF(A6="","",IF(ISNUMBER(SEARCH("GenSta",A6)),100*$L$2,IF(ISNUMBER(SEARCH("ES",A6)),50*$L$3,IF(ISNUMBER(SEARCH("Ld",A6)),2*O6*$L$4,"")))) -> 50 | F6: =IF(A6="","",IF(ISNUMBER(SEARCH("GenSta",A6)),"qgini",IF(ISNUMBER(SEARCH("ES",A6)),"qgini",IF(ISNUMBER(SEARCH("Ld",A6)),"qlini","")))) -> qgini | G6: =IF(A6="","",IF(ISNUMBER(SEARCH("GenSta",A6)),-E6,IF(ISNUMBER(SEARCH("ES",A6)),D6,IF(ISNUMBER(SEARCH("Ld",A6)),-E6,"")))) -> -50 | H6: =IF(A6="","",IF(ISNUMBER(SEARCH("GenSta",A6)),E6,IF(ISNUMBER(SEARCH("ES",A6)),E6,IF(ISNUMBER(SEARCH("Ld",A6)),E6,"")))) -> 50 | N6: =IF((_xlfn.XLOOKUP(A6,StatGen!A:A,StatGen!B:B," ")=0),(""),(_xlfn.IFNA(_xlfn.XLOOKUP(A6,StatGen!A:A,StatGen!B:B," "),""))) -> 78.934044 | O6: =IF((_xlfn.XLOOKUP(A6,Loads!A:A,Loads!B:B," ")=0),(""),(_xlfn.IFNA(_xlfn.XLOOKUP(A6,Loads!A:A,Loads!B:B," "),""))) | S6: Gen17 | T6: ElmSym
A7: Ld94 | B7: =IF(A7="","",IF(ISNUMBER(SEARCH("GenSta",A7)),"ElmGenstat",IF(ISNUMBER(SEARCH("ES",A7)),"ElmGenstat",IF(ISNUMBER(SEARCH("Ld",A7)),"ElmLod","")))) -> ElmLod | C7: =IF(A7="","",IF(ISNUMBER(SEARCH("GenSta",A7)),"pgini",IF(ISNUMBER(SEARCH("ES",A7)),"pgini",IF(ISNUMBER(SEARCH("Ld",A7)),"plini","")))) -> plini | D7: =IF(A7="","",IF(ISNUMBER(SEARCH("GenSta",A7)),0,IF(ISNUMBER(SEARCH("ES",A7)),-50*$L$3,IF(ISNUMBER(SEARCH("Ld",A7)),0.2*E7,"")))) -> 13.630713 | E7: =IF(A7="","",IF(ISNUMBER(SEARCH("GenSta",A7)),100*$L$2,IF(ISNUMBER(SEARCH("ES",A7)),50*$L$3,IF(ISNUMBER(SEARCH("Ld",A7)),2*O7*$L$4,"")))) -> 68.153565 | F7: =IF(A7="","",IF(ISNUMBER(SEARCH("GenSta",A7)),"qgini",IF(ISNUMBER(SEARCH("ES",A7)),"qgini",IF(ISNUMBER(SEARCH("Ld",A7)),"qlini","")))) -> qlini | G7: =IF(A7="","",IF(ISNUMBER(SEARCH("GenSta",A7)),-E7,IF(ISNUMBER(SEARCH("ES",A7)),D7,IF(ISNUMBER(SEARCH("Ld",A7)),-E7,"")))) -> -68.153565 | H7: =IF(A7="","",IF(ISNUMBER(SEARCH("GenSta",A7)),E7,IF(ISNUMBER(SEARCH("ES",A7)),E7,IF(ISNUMBER(SEARCH("Ld",A7)),E7,"")))) -> 68.153565 | N7: =IF((_xlfn.XLOOKUP(A7,StatGen!A:A,StatGen!B:B," ")=0),(""),(_xlfn.IFNA(_xlfn.XLOOKUP(A7,StatGen!A:A,StatGen!B:B," "),""))) | O7: =IF((_xlfn.XLOOKUP(A7,Loads!A:A,Loads!B:B," ")=0),(""),(_xlfn.IFNA(_xlfn.XLOOKUP(A7,Loads!A:A,Loads!B:B," "),""))) -> 34.076782 | S7: Gen2 | T7: ElmSym
A8: ES11 | B8: =IF(A8="","",IF(ISNUMBER(SEARCH("GenSta",A8)),"ElmGenstat",IF(ISNUMBER(SEARCH("ES",A8)),"ElmGenstat",IF(ISNUMBER(SEARCH("Ld",A8)),"ElmLod","")))) -> ElmGenstat | C8: =IF(A8="","",IF(ISNUMBER(SEARCH("GenSta",A8)),"pgini",IF(ISNUMBER(SEARCH("ES",A8)),"pgini",IF(ISNUMBER(SEARCH("Ld",A8)),"plini","")))) -> pgini | D8: =IF(A8="","",IF(ISNUMBER(SEARCH("GenSta",A8)),0,IF(ISNUMBER(SEARCH("ES",A8)),-50*$L$3,IF(ISNUMBER(SEARCH("Ld",A8)),0.2*E8,"")))) -> -50 | E8: =IF(A8="","",IF(ISNUMBER(SEARCH("GenSta",A8)),100,IF(ISNUMBER(SEARCH("ES",A8)),50*$L$3,IF(ISNUMBER(SEARCH("Ld",A8)),2*O8,"")))) -> 50 | F8: =IF(A8="","",IF(ISNUMBER(SEARCH("GenSta",A8)),"qgini",IF(ISNUMBER(SEARCH("ES",A8)),"qgini",IF(ISNUMBER(SEARCH("Ld",A8)),"qlini","")))) -> qgini | G8: =IF(A8="","",IF(ISNUMBER(SEARCH("GenSta",A8)),-E8,IF(ISNUMBER(SEARCH("ES",A8)),D8,IF(ISNUMBER(SEARCH("Ld",A8)),-E8,"")))) -> -50 | H8: =IF(A8="","",IF(ISNUMBER(SEARCH("GenSta",A8)),E8,IF(ISNUMBER(SEARCH("ES",A8)),E8,IF(ISNUMBER(SEARCH("Ld",A8)),E8,"")))) -> 50 | N8: =IF((_xlfn.XLOOKUP(A8,StatGen!A:A,StatGen!B:B," ")=0),(""),(_xlfn.IFNA(_xlfn.XLOOKUP(A8,StatGen!A:A,StatGen!B:B," "),""))) -> 89.443676 | O8: =IF((_xlfn.XLOOKUP(A8,Loads!A:A,Loads!B:B," ")=0),(""),(_xlfn.IFNA(_xlfn.XLOOKUP(A8,Loads!A:A,Loads!B:B," "),"")))
A9: GenSta71 | B9: =IF(A9="","",IF(ISNUMBER(SEARCH("GenSta",A9)),"ElmGenstat",IF(ISNUMBER(SEARCH("ES",A9)),"ElmGenstat",IF(ISNUMBER(SEARCH("Ld",A9)),"ElmLod","")))) -> ElmGenstat | C9: =IF(A9="","",IF(ISNUMBER(SEARCH("GenSta",A9)),"pgini",IF(ISNUMBER(SEARCH("ES",A9)),"pgini",IF(ISNUMBER(SEARCH("Ld",A9)),"plini","")))) -> pgini | D9: =IF(A9="","",IF(ISNUMBER(SEARCH("GenSta",A9)),0,IF(ISNUMBER(SEARCH("ES",A9)),-50*$L$3,IF(ISNUMBER(SEARCH("Ld",A9)),0.2*E9,"")))) -> 0 | E9: =IF(A9="","",IF(ISNUMBER(SEARCH("GenSta",A9)),100,IF(ISNUMBER(SEARCH("ES",A9)),50*$L$3,IF(ISNUMBER(SEARCH("Ld",A9)),2*O9,"")))) -> 100 | F9: =IF(A9="","",IF(ISNUMBER(SEARCH("GenSta",A9)),"qgini",IF(ISNUMBER(SEARCH("ES",A9)),"qgini",IF(ISNUMBER(SEARCH("Ld",A9)),"qlini","")))) -> qgini | G9: =IF(A9="","",IF(ISNUMBER(SEARCH("GenSta",A9)),-E9,IF(ISNUMBER(SEARCH("ES",A9)),D9,IF(ISNUMBER(SEARCH("Ld",A9)),-E9,"")))) -> -100 | H9: =IF(A9="","",IF(ISNUMBER(SEARCH("GenSta",A9)),E9,IF(ISNUMBER(SEARCH("ES",A9)),E9,IF(ISNUMBER(SEARCH("Ld",A9)),E9,"")))) -> 100 | N9: =IF((_xlfn.XLOOKUP(A9,StatGen!A:A,StatGen!B:B," ")=0),(""),(_xlfn.IFNA(_xlfn.XLOOKUP(A9,StatGen!A:A,StatGen!B:B," "),""))) -> 80 | O9: =IF((_xlfn.XLOOKUP(A9,Loads!A:A,Loads!B:B," ")=0),(""),(_xlfn.IFNA(_xlfn.XLOOKUP(A9,Loads!A:A,Loads!B:B," "),"")))
A10: Ld79 | B10: =IF(A10="","",IF(ISNUMBER(SEARCH("GenSta",A10)),"ElmGenstat",IF(ISNUMBER(SEARCH("ES",A10)),"ElmGenstat",IF(ISNUMBER(SEARCH("Ld",A10)),"ElmLod","")))) -> ElmLod | C10: =IF(A10="","",IF(ISNUMBER(SEARCH("GenSta",A10)),"pgini",IF(ISNUMBER(SEARCH("ES",A10)),"pgini",IF(ISNUMBER(SEARCH("Ld",A10)),"plini","")))) -> plini | D10: =IF(A10="","",IF(ISNUMBER(SEARCH("GenSta",A10)),0,IF(ISNUMBER(SEARCH("ES",A10)),-50*$L$3,IF(ISNUMBER(SEARCH("Ld",A10)),0.2*E10,"")))) -> 20.571703 | E10: =IF(A10="","",IF(ISNUMBER(SEARCH("GenSta",A10)),100,IF(ISNUMBER(SEARCH("ES",A10)),50*$L$3,IF(ISNUMBER(SEARCH("Ld",A10)),2*O10,"")))) -> 102.85852 | F10: =IF(A10="","",IF(ISNUMBER(SEARCH("GenSta",A10)),"qgini",IF(ISNUMBER(SEARCH("ES",A10)),"qgini",IF(ISNUMBER(SEARCH("Ld",A10)),"qlini","")))) -> qlini | G10: =IF(A10="","",IF(ISNUMBER(SEARCH("GenSta",A10)),-E10,IF(ISNUMBER(SEARCH("ES",A10)),D10,IF(ISNUMBER(SEARCH("Ld",A10)),-E10,"")))) -> -102.85852 | H10: =IF(A10="","",IF(ISNUMBER(SEARCH("GenSta",A10)),E10,IF(ISNUMBER(SEARCH("ES",A10)),E10,IF(ISNUMBER(SEARCH("Ld",A10)),E10,"")))) -> 102.85852 | N10: =IF((_xlfn.XLOOKUP(A10,StatGen!A:A,StatGen!B:B," ")=0),(""),(_xlfn.IFNA(_xlfn.XLOOKUP(A10,StatGen!A:A,StatGen!B:B," "),""))) | O10: =IF((_xlfn.XLOOKUP(A10,Loads!A:A,Loads!B:B," ")=0),(""),(_xlfn.IFNA(_xlfn.XLOOKUP(A10,Loads!A:A,Loads!B:B," "),""))) -> 51.429258
A11: Ld14 | B11: =IF(A11="","",IF(ISNUMBER(SEARCH("GenSta",A11)),"ElmGenstat",IF(ISNUMBER(SEARCH("ES",A11)),"ElmGenstat",IF(ISNUMBER(SEARCH("Ld",A11)),"ElmLod","")))) -> ElmLod | C11: =IF(A11="","",IF(ISNUMBER(SEARCH("GenSta",A11)),"pgini",IF(ISNUMBER(SEARCH("ES",A11)),"pgini",IF(ISNUMBER(SEARCH("Ld",A11)),"plini","")))) -> plini | D11: =IF(A11="","",IF(ISNUMBER(SEARCH("GenSta",A11)),0,IF(ISNUMBER(SEARCH("ES",A11)),-50*$L$3,IF(ISNUMBER(SEARCH("Ld",A11)),0.2*E11,"")))) -> 18.50036 | E11: =IF(A11="","",IF(ISNUMBER(SEARCH("GenSta",A11)),100,IF(ISNUMBER(SEARCH("ES",A11)),50*$L$3,IF(ISNUMBER(SEARCH("Ld",A11)),2*O11,"")))) -> 92.501801 | F11: =IF(A11="","",IF(ISNUMBER(SEARCH("GenSta",A11)),"qgini",IF(ISNUMBER(SEARCH("ES",A11)),"qgini",IF(ISNUMBER(SEARCH("Ld",A11)),"qlini","")))) -> qlini | G11: =IF(A11="","",IF(ISNUMBER(SEARCH("GenSta",A11)),-E11,IF(ISNUMBER(SEARCH("ES",A11)),D11,IF(ISNUMBER(SEARCH("Ld",A11)),-E11,"")))) -> -92.501801 | H11: =IF(A11="","",IF(ISNUMBER(SEARCH("GenSta",A11)),E11,IF(ISNUMBER(SEARCH("ES",A11)),E11,IF(ISNUMBER(SEARCH("Ld",A11)),E11,"")))) -> 92.501801 | N11: =IF((_xlfn.XLOOKUP(A11,StatGen!A:A,StatGen!B:B," ")=0),(""),(_xlfn.IFNA(_xlfn.XLOOKUP(A11,StatGen!A:A,StatGen!B:B," "),""))) | O11: =IF((_xlfn.XLOOKUP(A11,Loads!A:A,Loads!B:B," ")=0),(""),(_xlfn.IFNA(_xlfn.XLOOKUP(A11,Loads!A:A,Loads!B:B," "),""))) -> 46.250901
A12: GenSta76 | B12: =IF(A12="","",IF(ISNUMBER(SEARCH("GenSta",A12)),"ElmGenstat",IF(ISNUMBER(SEARCH("ES",A12)),"ElmGenstat",IF(ISNUMBER(SEARCH("Ld",A12)),"ElmLod","")))) -> ElmGenstat | C12: =IF(A12="","",IF(ISNUMBER(SEARCH("GenSta",A12)),"pgini",IF(ISNUMBER(SEARCH("ES",A12)),"pgini",IF(ISNUMBER(SEARCH("Ld",A12)),"plini","")))) -> pgini | D12: =IF(A12="","",IF(ISNUMBER(SEARCH("GenSta",A12)),0,IF(ISNUMBER(SEARCH("ES",A12)),-50*$L$3,IF(ISNUMBER(SEARCH("Ld",A12)),0.2*E12,"")))) -> 0 | E12: =IF(A12="","",IF(ISNUMBER(SEARCH("GenSta",A12)),100,IF(ISNUMBER(SEARCH("ES",A12)),50*$L$3,IF(ISNUMBER(SEARCH("Ld",A12)),2*O12,"")))) -> 100 | F12: =IF(A12="","",IF(ISNUMBER(SEARCH("GenSta",A12)),"qgini",IF(ISNUMBER(SEARCH("ES",A12)),"qgini",IF(ISNUMBER(SEARCH("Ld",A12)),"qlini","")))) -> qgini | G12: =IF(A12="","",IF(ISNUMBER(SEARCH("GenSta",A12)),-E12,IF(ISNUMBER(SEARCH("ES",A12)),D12,IF(ISNUMBER(SEARCH("Ld",A12)),-E12,"")))) -> -100 | H12: =IF(A12="","",IF(ISNUMBER(SEARCH("GenSta",A12)),E12,IF(ISNUMBER(SEARCH("ES",A12)),E12,IF(ISNUMBER(SEARCH("Ld",A12)),E12,"")))) -> 100 | N12: =IF((_xlfn.XLOOKUP(A12,StatGen!A:A,StatGen!B:B," ")=0),(""),(_xlfn.IFNA(_xlfn.XLOOKUP(A12,StatGen!A:A,StatGen!B:B," "),""))) -> 63.5 | O12: =IF((_xlfn.XLOOKUP(A12,Loads!A:A,Loads!B:B," ")=0),(""),(_xlfn.IFNA(_xlfn.XLOOKUP(A12,Loads!A:A,Loads!B:B," "),"")))
A13: GenSta2 | B13: =IF(A13="","",IF(ISNUMBER(SEARCH("GenSta",A13)),"ElmGenstat",IF(ISNUMBER(SEARCH("ES",A13)),"ElmGenstat",IF(ISNUMBER(SEARCH("Ld",A13)),"ElmLod","")))) -> ElmGenstat | C13: =IF(A13="","",IF(ISNUMBER(SEARCH("GenSta",A13)),"pgini",IF(ISNUMBER(SEARCH("ES",A13)),"pgini",IF(ISNUMBER(SEARCH("Ld",A13)),"plini","")))) -> pgini | D13: =IF(A13="","",IF(ISNUMBER(SEARCH("GenSta",A13)),0,IF(ISNUMBER(SEARCH("ES",A13)),-50*$L$3,IF(ISNUMBER(SEARCH("Ld",A13)),0.2*E13,"")))) -> 0 | E13: =IF(A13="","",IF(ISNUMBER(SEARCH("GenSta",A13)),100,IF(ISNUMBER(SEARCH("ES",A13)),50*$L$3,IF(ISNUMBER(SEARCH("Ld",A13)),2*O13,"")))) -> 100 | F13: =IF(A13="","",IF(ISNUMBER(SEARCH("GenSta",A13)),"qgini",IF(ISNUMBER(SEARCH("ES",A13)),"qgini",IF(ISNUMBER(SEARCH("Ld",A13)),"qlini","")))) -> qgini | G13: =IF(A13="","",IF(ISNUMBER(SEARCH("GenSta",A13)),-E13,IF(ISNUMBER(SEARCH("ES",A13)),D13,IF(ISNUMBER(SEARCH("Ld",A13)),-E13,"")))) -> -100 | H13: =IF(A13="","",IF(ISNUMBER(SEARCH("GenSta",A13)),E13,IF(ISNUMBER(SEARCH("ES",A13)),E13,IF(ISNUMBER(SEARCH("Ld",A13)),E13,"")))) -> 100 | N13: =IF((_xlfn.XLOOKUP(A13,StatGen!A:A,StatGen!B:B," ")=0),(""),(_xlfn.IFNA(_xlfn.XLOOKUP(A13,StatGen!A:A,StatGen!B:B," "),""))) -> 66.9 | O13: =IF((_xlfn.XLOOKUP(A13,Loads!A:A,Loads!B:B," ")=0),(""),(_xlfn.IFNA(_xlfn.XLOOKUP(A13,Loads!A:A,Loads!B:B," "),"")))
B14: =IF(A14="","",IF(ISNUMBER(SEARCH("GenSta",A14)),"ElmGenstat",IF(ISNUMBER(SEARCH("ES",A14)),"ElmGenstat",IF(ISNUMBER(SEARCH("Ld",A14)),"ElmLod","")))) | C14: =IF(A14="","",IF(ISNUMBER(SEARCH("GenSta",A14)),"pgini",IF(ISNUMBER(SEARCH("ES",A14)),"pgini",IF(ISNUMBER(SEARCH("Ld",A14)),"plini","")))) | D14: =IF(A14="","",IF(ISNUMBER(SEARCH("GenSta",A14)),0,IF(ISNUMBER(SEARCH("ES",A14)),-50*$L$3,IF(ISNUMBER(SEARCH("Ld",A14)),0.2*E14,"")))) | E14: =IF(A14="","",IF(ISNUMBER(SEARCH("GenSta",A14)),100,IF(ISNUMBER(SEARCH("ES",A14)),50*$L$3,IF(ISNUMBER(SEARCH("Ld",A14)),2*O14,"")))) | F14: =IF(A14="","",IF(ISNUMBER(SEARCH("GenSta",A14)),"qgini",IF(ISNUMBER(SEARCH("ES",A14)),"qgini",IF(ISNUMBER(SEARCH("Ld",A14)),"qlini","")))) | G14: =IF(A14="","",IF(ISNUMBER(SEARCH("GenSta",A14)),-E14,IF(ISNUMBER(SEARCH("ES",A14)),D14,IF(ISNUMBER(SEARCH("Ld",A14)),-E14,"")))) | H14: =IF(A14="","",IF(ISNUMBER(SEARCH("GenSta",A14)),E14,IF(ISNUMBER(SEARCH("ES",A14)),E14,IF(ISNUMBER(SEARCH("Ld",A14)),E14,"")))) | N14: =IF((_xlfn.XLOOKUP(A14,StatGen!A:A,StatGen!B:B," ")=0),(""),(_xlfn.IFNA(_xlfn.XLOOKUP(A14,StatGen!A:A,StatGen!B:B," "),""))) | O14: =IF((_xlfn.XLOOKUP(A14,Loads!A:A,Loads!B:B," ")=0),(""),(_xlfn.IFNA(_xlfn.XLOOKUP(A14,Loads!A:A,Loads!B:B," "),"")))
